Workbook

Sheet IIRUP
A1: PAR Number | B1: Series Number | C1: Article | D1: Property Number | E1: Type of Properties | F1: Brand | G1: Model | H1: Serial Number | I1: Processor | J1: RAM | K1: Storage | L1: Color | M1: Other Description | N1: Unit of Measure | O1: Unit Value | P1: Total Value | Q1: Value Category | R1: Qty | PCard | S1: Qty | PCount | T1: S|O Qty | U1: S|O Value | V1: Date of Acquisition | W1: Location | X1: Accountable Person | Y1: Position | Z1: Source of Fund | AA1: Full Specifications | AB1: Issued ICS
B2: 1 | C2: Furniture and Fixture | D2: =CONCATENATE(TEXT(Table164[[#This Row],[Date of Acquisition]],"yyyy")," - ", VLOOKUP(Table164[[#This Row],[Article]],'Data Validation'!$A$2:$B$16,2,FALSE)," - ",TEXT(Table164[[#This Row],[Series Number]],"0000")," - ",TEXT(VLOOKUP(Table164[[#This Row],[Location]],'Data Validation'!$A$20:$B$47,2,FALSE),"00")) -> 2010 - 07 - 01 - 0001 - 01A | E2: Frame Chalk & Eraser Holder Kiln Dried Size | F2: n|a | G2: n|a | H2: n|a | I2: n|a | J2: n|a | K2: n|a | L2: n|a | M2: Frame Chalk & Eraser Holder Kiln Dried Size | N2: unit | O2: 50000 | P2: =Table164[[#This Row],[Unit Value]]*Table164[[#This Row],[Qty | PCount]] -> 50000 | Q2: =IF(Table164[[#This Row],[Unit Value]]<=4999,"Low-Value Asset","High-Value Asset") -> High-Value Asset | R2: 1 | S2: 1 | T2: 0 | U2: 0 | V2: 40513 | W2: 001A - Office of the School Division Superintendent | X2: - | Y2: - | Z2: Unserviceable | AA2: =CONCATENATE(Table164[[#This Row],[Other Description]]," - ",IF(Table164[[#This Row],[Brand]]="n|a","",CONCATENATE("Brand: ",Table164[[#This Row],[Brand]]," - ")),IF(Table164[[#This Row],[Model]]="n|a","",CONCATENATE("Model: ",Table164[[#This Row],[Model]]," - ")),IF(Table164[[#This Row],[Serial Number]]="n|a","",CONCATENATE("SN: ",Table164[[#This Row],[Serial Number]]," - ")),IF(Table164[[#This Row],[Processor]]="n|a","",CONCATENATE("Processor: ",Table164[[#This Row],[Processor]]," - ")),IF(Table164[[#This Row],[RAM]]="n|a","",CONCATENATE("RAM: ",Table164[[#This Row],[RAM]]," - ")),IF(Table164[[#This Row],[Storage]]="n|a","",CONCATENATE("Storage: ",Table164[[#This Row],[Storage]]," - ")),IF(Table164[[#This Row],[Color]]="n|a","",CONCATENATE("Color: ",Table164[[#This Row],[Color]]))) -> Frame Chalk & Eraser Holder Kiln Dried Size -
B3: 1 | C3: Furniture and Fixture | D3: =CONCATENATE(TEXT(Table164[[#This Row],[Date of Acquisition]],"yyyy")," - ", VLOOKUP(Table164[[#This Row],[Article]],'Data Validation'!$A$2:$B$16,2,FALSE)," - ",TEXT(Table164[[#This Row],[Series Number]],"0000")," - ",TEXT(VLOOKUP(Table164[[#This Row],[Location]],'Data Validation'!$A$20:$B$47,2,FALSE),"00")) -> 2017 - 07 - 01 - 0001 - 01A | E3: Electronic Magnifying Glass (SPED) | F3: n|a | G3: n|a | H3: n|a | I3: n|a | J3: n|a | K3: n|a | L3: n|a | M3: Electronic Magnifying Glass (SPED) | N3: unit | O3: 56817 | P3: =Table164[[#This Row],[Unit Value]]*Table164[[#This Row],[Qty | PCount]] -> 56817 | Q3: =IF(Table164[[#This Row],[Unit Value]]<=4999,"Low-Value Asset","High-Value Asset") -> High-Value Asset | R3: 1 | S3: 1 | T3: 0 | U3: 0 | V3: 43070 | W3: 001A - Office of the School Division Superintendent | X3: - | Y3: - | Z3: Unserviceable | AA3: =CONCATENATE(Table164[[#This Row],[Other Description]]," - ",IF(Table164[[#This Row],[Brand]]="n|a","",CONCATENATE("Brand: ",Table164[[#This Row],[Brand]]," - ")),IF(Table164[[#This Row],[Model]]="n|a","",CONCATENATE("Model: ",Table164[[#This Row],[Model]]," - ")),IF(Table164[[#This Row],[Serial Number]]="n|a","",CONCATENATE("SN: ",Table164[[#This Row],[Serial Number]]," - ")),IF(Table164[[#This Row],[Processor]]="n|a","",CONCATENATE("Processor: ",Table164[[#This Row],[Processor]]," - ")),IF(Table164[[#This Row],[RAM]]="n|a","",CONCATENATE("RAM: ",Table164[[#This Row],[RAM]]," - ")),IF(Table164[[#This Row],[Storage]]="n|a","",CONCATENATE("Storage: ",Table164[[#This Row],[Storage]]," - ")),IF(Table164[[#This Row],[Color]]="n|a","",CONCATENATE("Color: ",Table164[[#This Row],[Color]]))) -> Electronic Magnifying Glass (SPED) -
B4: 1 | C4: ICT Equipment | D4: =CONCATENATE(TEXT(Table164[[#This Row],[Date of Acquisition]],"yyyy")," - ", VLOOKUP(Table164[[#This Row],[Article]],'Data Validation'!$A$2:$B$16,2,FALSE)," - ",TEXT(Table164[[#This Row],[Series Number]],"0000")," - ",TEXT(VLOOKUP(Table164[[#This Row],[Location]],'Data Validation'!$A$20:$B$47,2,FALSE),"00")) -> 2005 - 05 - 03 - 0001 - 01A | E4: Desktop Computer | F4: n|a | G4: n|a | H4: n|a | I4: Pentium 4 | J4: n|a | K4: n|a | L4: Black | M4: Desktop Computer with Printer | N4: unit | O4: 65500 | P4: =Table164[[#This Row],[Unit Value]]*Table164[[#This Row],[Qty | PCount]] -> 65500 | Q4: =IF(Table164[[#This Row],[Unit Value]]<=4999,"Low-Value Asset","High-Value Asset") -> High-Value Asset | R4: 1 | S4: 1 | T4: 0 | U4: 0 | V4: 38498 | W4: 001A - Office of the School Division Superintendent | Z4: Unserviceable | AA4: =CONCATENATE(Table164[[#This Row],[Other Description]]," - ",IF(Table164[[#This Row],[Brand]]="n|a","",CONCATENATE("Brand: ",Table164[[#This Row],[Brand]]," - ")),IF(Table164[[#This Row],[Model]]="n|a","",CONCATENATE("Model: ",Table164[[#This Row],[Model]]," - ")),IF(Table164[[#This Row],[Serial Number]]="n|a","",CONCATENATE("SN: ",Table164[[#This Row],[Serial Number]]," - ")),IF(Table164[[#This Row],[Processor]]="n|a","",CONCATENATE("Processor: ",Table164[[#This Row],[Processor]]," - ")),IF(Table164[[#This Row],[RAM]]="n|a","",CONCATENATE("RAM: ",Table164[[#This Row],[RAM]]," - ")),IF(Table164[[#This Row],[Storage]]="n|a","",CONCATENATE("Storage: ",Table164[[#This Row],[Storage]]," - ")),IF(Table164[[#This Row],[Color]]="n|a","",CONCATENATE("Color: ",Table164[[#This Row],[Color]]))) -> Desktop Computer with Printer - Processor: Pentium 4 - Color: Black
B5: 2 | C5: ICT Equipment | D5: =CONCATENATE(TEXT(Table164[[#This Row],[Date of Acquisition]],"yyyy")," - ", VLOOKUP(Table164[[#This Row],[Article]],'Data Validation'!$A$2:$B$16,2,FALSE)," - ",TEXT(Table164[[#This Row],[Series Number]],"0000")," - ",TEXT(VLOOKUP(Table164[[#This Row],[Location]],'Data Validation'!$A$20:$B$47,2,FALSE),"00")) -> 2005 - 05 - 03 - 0002 - 01A | E5: Desktop Computer | F5: Compaq | G5: n|a | H5: n|a | I5: n|a | J5: n|a | K5: n|a | L5: Black | M5: Desktop Computer | N5: unit | O5: 125000 | P5: =Table164[[#This Row],[Unit Value]]*Table164[[#This Row],[Qty | PCount]] -> 125000 | Q5: =IF(Table164[[#This Row],[Unit Value]]<=4999,"Low-Value Asset","High-Value Asset") -> High-Value Asset | R5: 1 | S5: 1 | T5: 0 | U5: 0 | V5: 38580 | W5: 001A - Office of the School Division Superintendent | Z5: Unserviceable | AA5: =CONCATENATE(Table164[[#This Row],[Other Description]]," - ",IF(Table164[[#This Row],[Brand]]="n|a","",CONCATENATE("Brand: ",Table164[[#This Row],[Brand]]," - ")),IF(Table164[[#This Row],[Model]]="n|a","",CONCATENATE("Model: ",Table164[[#This Row],[Model]]," - ")),IF(Table164[[#This Row],[Serial Number]]="n|a","",CONCATENATE("SN: ",Table164[[#This Row],[Serial Number]]," - ")),IF(Table164[[#This Row],[Processor]]="n|a","",CONCATENATE("Processor: ",Table164[[#This Row],[Processor]]," - ")),IF(Table164[[#This Row],[RAM]]="n|a","",CONCATENATE("RAM: ",Table164[[#This Row],[RAM]]," - ")),IF(Table164[[#This Row],[Storage]]="n|a","",CONCATENATE("Storage: ",Table164[[#This Row],[Storage]]," - ")),IF(Table164[[#This Row],[Color]]="n|a","",CONCATENATE("Color: ",Table164[[#This Row],[Color]]))) -> Desktop Computer - Brand: Compaq - Color: Black
B6: 3 | C6: ICT Equipment | D6: =CONCATENATE(TEXT(Table164[[#This Row],[Date of Acquisition]],"yyyy")," - ", VLOOKUP(Table164[[#This Row],[Article]],'Data Validation'!$A$2:$B$16,2,FALSE)," - ",TEXT(Table164[[#This Row],[Series Number]],"0000")," - ",TEXT(VLOOKUP(Table164[[#This Row],[Location]],'Data Validation'!$A$20:$B$47,2,FALSE),"00")) -> 2005 - 05 - 03 - 0003 - 01A | E6: Desktop Computer | F6: n|a | G6: n|a | H6: n|a | I6: Pentium 4 | J6: n|a | K6: n|a | L6: Black | M6: Desktop Computer with Printer and Computer Table | N6: unit | O6: 66500 | P6: =Table164[[#This Row],[Unit Value]]*Table164[[#This Row],[Qty | PCount]] -> 66500 | Q6: =IF(Table164[[#This Row],[Unit Value]]<=4999,"Low-Value Asset","High-Value Asset") -> High-Value Asset | R6: 1 | S6: 1 | T6: 0 | U6: 0 | V6: 38580 | W6: 001A - Office of the School Division Superintendent | Z6: Unserviceable | AA6: =CONCATENATE(Table164[[#This Row],[Other Description]]," - ",IF(Table164[[#This Row],[Brand]]="n|a","",CONCATENATE("Brand: ",Table164[[#This Row],[Brand]]," - ")),IF(Table164[[#This Row],[Model]]="n|a","",CONCATENATE("Model: ",Table164[[#This Row],[Model]]," - ")),IF(Table164[[#This Row],[Serial Number]]="n|a","",CONCATENATE("SN: ",Table164[[#This Row],[Serial Number]]," - ")),IF(Table164[[#This Row],[Processor]]="n|a","",CONCATENATE("Processor: ",Table164[[#This Row],[Processor]]," - ")),IF(Table164[[#This Row],[RAM]]="n|a","",CONCATENATE("RAM: ",Table164[[#This Row],[RAM]]," - ")),IF(Table164[[#This Row],[Storage]]="n|a","",CONCATENATE("Storage: ",Table164[[#This Row],[Storage]]," - ")),IF(Table164[[#This Row],[Color]]="n|a","",CONCATENATE("Color: ",Table164[[#This Row],[Color]]))) -> Desktop Computer with Printer and Computer Table - Processor: Pentium 4 - Color: Black
B7: 4 | C7: ICT Equipment | D7: =CONCATENATE(TEXT(Table164[[#This Row],[Date of Acquisition]],"yyyy")," - ", VLOOKUP(Table164[[#This Row],[Article]],'Data Validation'!$A$2:$B$16,2,FALSE)," - ",TEXT(Table164[[#This Row],[Series Number]],"0000")," - ",TEXT(VLOOKUP(Table164[[#This Row],[Location]],'Data Validation'!$A$20:$B$47,2,FALSE),"00")) -> 2005 - 05 - 03 - 0004 - 01A | E7: Printing Machine | F7: Epson | G7: 2175 | H7: n|a | I7: n|a | J7: n|a | K7: n|a | L7: n|a | M7: Printing Machine | N7: unit | O7: 58500 | P7: =Table164[[#This Row],[Unit Value]]*Table164[[#This Row],[Qty | PCount]] -> 58500 | Q7: =IF(Table164[[#This Row],[Unit Value]]<=4999,"Low-Value Asset","High-Value Asset") -> High-Value Asset | R7: 1 | S7: 1 | T7: 0 | U7: 0 | V7: 38687 | W7: 001A - Office of the School Division Superintendent | X7: - | Y7: - | Z7: Unserviceable | AA7: =CONCATENATE(Table164[[#This Row],[Other Description]]," - ",IF(Table164[[#This Row],[Brand]]="n|a","",CONCATENATE("Brand: ",Table164[[#This Row],[Brand]]," - ")),IF(Table164[[#This Row],[Model]]="n|a","",CONCATENATE("Model: ",Table164[[#This Row],[Model]]," - ")),IF(Table164[[#This Row],[Serial Number]]="n|a","",CONCATENATE("SN: ",Table164[[#This Row],[Serial Number]]," - ")),IF(Table164[[#This Row],[Processor]]="n|a","",CONCATENATE("Processor: ",Table164[[#This Row],[Processor]]," - ")),IF(Table164[[#This Row],[RAM]]="n|a","",CONCATENATE("RAM: ",Table164[[#This Row],[RAM]]," - ")),IF(Table164[[#This Row],[Storage]]="n|a","",CONCATENATE("Storage: ",Table164[[#This Row],[Storage]]," - ")),IF(Table164[[#This Row],[Color]]="n|a","",CONCATENATE("Color: ",Table164[[#This Row],[Color]]))) -> Printing Machine - Brand: Epson - Model: 2175 -
B8: 1 | C8: ICT Equipment | D8: =CONCATENATE(TEXT(Table164[[#This Row],[Date of Acquisition]],"yyyy")," - ", VLOOKUP(Table164[[#This Row],[Article]],'Data Validation'!$A$2:$B$16,2,FALSE)," - ",TEXT(Table164[[#This Row],[Series Number]],"0000")," - ",TEXT(VLOOKUP(Table164[[#This Row],[Location]],'Data Validation'!$A$20:$B$47,2,FALSE),"00")) -> 2006 - 05 - 03 - 0001 - 01A | E8: Desktop Computer | F8: IBM | G8: n|a | H8: n|a | I8: n|a | J8: n|a | K8: n|a | L8: Black | M8: Compatible Computer System with Cog Manipulatives | N8: unit | O8: 250000 | P8: =Table164[[#This Row],[Unit Value]]*Table164[[#This Row],[Qty | PCount]] -> 250000 | Q8: =IF(Table164[[#This Row],[Unit Value]]<=4999,"Low-Value Asset","High-Value Asset") -> High-Value Asset | R8: 1 | S8: 1 | T8: 0 | U8: 0 | V8: 39046 | W8: 001A - Office of the School Division Superintendent | Z8: Unserviceable | AA8: =CONCATENATE(Table164[[#This Row],[Other Description]]," - ",IF(Table164[[#This Row],[Brand]]="n|a","",CONCATENATE("Brand: ",Table164[[#This Row],[Brand]]," - ")),IF(Table164[[#This Row],[Model]]="n|a","",CONCATENATE("Model: ",Table164[[#This Row],[Model]]," - ")),IF(Table164[[#This Row],[Serial Number]]="n|a","",CONCATENATE("SN: ",Table164[[#This Row],[Serial Number]]," - ")),IF(Table164[[#This Row],[Processor]]="n|a","",CONCATENATE("Processor: ",Table164[[#This Row],[Processor]]," - ")),IF(Table164[[#This Row],[RAM]]="n|a","",CONCATENATE("RAM: ",Table164[[#This Row],[RAM]]," - ")),IF(Table164[[#This Row],[Storage]]="n|a","",CONCATENATE("Storage: ",Table164[[#This Row],[Storage]]," - ")),IF(Table164[[#This Row],[Color]]="n|a","",CONCATENATE("Color: ",Table164[[#This Row],[Color]]))) -> Compatible Computer System with Cog Manipulatives - Brand: IBM - Color: Black
B9: 1 | C9: ICT Equipment | D9: =CONCATENATE(TEXT(Table164[[#This Row],[Date of Acquisition]],"yyyy")," - ", VLOOKUP(Table164[[#This Row],[Article]],'Data Validation'!$A$2:$B$16,2,FALSE)," - ",TEXT(Table164[[#This Row],[Series Number]],"0000")," - ",TEXT(VLOOKUP(Table164[[#This Row],[Location]],'Data Validation'!$A$20:$B$47,2,FALSE),"00")) -> 2008 - 05 - 03 - 0001 - 01A | E9: Laptop | F9: n|a | G9: n|a | H9: n|a | I9: n|a | J9: n|a | K9: n|a | L9: n|a | M9: Laptop Computer | N9: unit | O9: 116800 | P9: =Table164[[#This Row],[Unit Value]]*Table164[[#This Row],[Qty | PCount]] -> 116800 | Q9: =IF(Table164[[#This Row],[Unit Value]]<=4999,"Low-Value Asset","High-Value Asset") -> High-Value Asset | R9: 1 | S9: 1 | T9: 0 | U9: 0 | V9: 39448 | W9: 001A - Office of the School Division Superintendent | Z9: Unserviceable | AA9: =CONCATENATE(Table164[[#This Row],[Other Description]]," - ",IF(Table164[[#This Row],[Brand]]="n|a","",CONCATENATE("Brand: ",Table164[[#This Row],[Brand]]," - ")),IF(Table164[[#This Row],[Model]]="n|a","",CONCATENATE("Model: ",Table164[[#This Row],[Model]]," - ")),IF(Table164[[#This Row],[Serial Number]]="n|a","",CONCATENATE("SN: ",Table164[[#This Row],[Serial Number]]," - ")),IF(Table164[[#This Row],[Processor]]="n|a","",CONCATENATE("Processor: ",Table164[[#This Row],[Processor]]," - ")),IF(Table164[[#This Row],[RAM]]="n|a","",CONCATENATE("RAM: ",Table164[[#This Row],[RAM]]," - ")),IF(Table164[[#This Row],[Storage]]="n|a","",CONCATENATE("Storage: ",Table164[[#This Row],[Storage]]," - ")),IF(Table164[[#This Row],[Color]]="n|a","",CONCATENATE("Color: ",Table164[[#This Row],[Color]]))) -> Laptop Computer -
B10: 1 | C10: ICT Equipment | D10: =CONCATENATE(TEXT(Table164[[#This Row],[Date of Acquisition]],"yyyy")," - ", VLOOKUP(Table164[[#This Row],[Article]],'Data Validation'!$A$2:$B$16,2,FALSE)," - ",TEXT(Table164[[#This Row],[Series Number]],"0000")," - ",TEXT(VLOOKUP(Table164[[#This Row],[Location]],'Data Validation'!$A$20:$B$47,2,FALSE),"00")) -> 2009 - 05 - 03 - 0001 - 01A | E10: Desktop Computer | F10: Lenovo | G10: ThinkCentre M58E | H10: n|a | I10: n|a | J10: n|a | K10: n|a | L10: Black | M10: Desktop Computer | N10: unit | O10: 74800 | P10: =Table164[[#This Row],[Unit Value]]*Table164[[#This Row],[Qty | PCount]] -> 74800 | Q10: =IF(Table164[[#This Row],[Unit Value]]<=4999,"Low-Value Asset","High-Value Asset") -> High-Value Asset | R10: 1 | S10: 1 | T10: 0 | U10: 0 | V10: 40058 | W10: 001A - Office of the School Division Superintendent | Z10: Unserviceable | AA10: =CONCATENATE(Table164[[#This Row],[Other Description]]," - ",IF(Table164[[#This Row],[Brand]]="n|a","",CONCATENATE("Brand: ",Table164[[#This Row],[Brand]]," - ")),IF(Table164[[#This Row],[Model]]="n|a","",CONCATENATE("Model: ",Table164[[#This Row],[Model]]," - ")),IF(Table164[[#This Row],[Serial Number]]="n|a","",CONCATENATE("SN: ",Table164[[#This Row],[Serial Number]]," - ")),IF(Table164[[#This Row],[Processor]]="n|a","",CONCATENATE("Processor: ",Table164[[#This Row],[Processor]]," - ")),IF(Table164[[#This Row],[RAM]]="n|a","",CONCATENATE("RAM: ",Table164[[#This Row],[RAM]]," - ")),IF(Table164[[#This Row],[Storage]]="n|a","",CONCATENATE("Storage: ",Table164[[#This Row],[Storage]]," - ")),IF(Table164[[#This Row],[Color]]="n|a","",CONCATENATE("Color: ",Table164[[#This Row],[Color]]))) -> Desktop Computer - Brand: Lenovo - Model: ThinkCentre M58E - Color: Black
B11: 1 | C11: ICT Equipment | D11: =CONCATENATE(TEXT(Table164[[#This Row],[Date of Acquisition]],"yyyy")," - ", VLOOKUP(Table164[[#This Row],[Article]],'Data Validation'!$A$2:$B$16,2,FALSE)," - ",TEXT(Table164[[#This Row],[Series Number]],"0000")," - ",TEXT(VLOOKUP(Table164[[#This Row],[Location]],'Data Validation'!$A$20:$B$47,2,FALSE),"00")) -> 2017 - 05 - 03 - 0001 - 01A | E11: Laptop | F11: Acer | G11: Switch Alpha 12 | H11: n|a | I11: n|a | J11: n|a | K11: n|a | L11: Black | M11: Laptop | N11: unit | O11: 104444 | P11: =Table164[[#This Row],[Unit Value]]*Table164[[#This Row],[Qty | PCount]] -> 104444 | Q11: =IF(Table164[[#This Row],[Unit Value]]<=4999,"Low-Value Asset","High-Value Asset") -> High-Value Asset | R11: 1 | S11: 1 | T11: 0 | U11: 0 | V11: 42919 | W11: 001A - Office of the School Division Superintendent | Z11: Unserviceable | AA11: =CONCATENATE(Table164[[#This Row],[Other Description]]," - ",IF(Table164[[#This Row],[Brand]]="n|a","",CONCATENATE("Brand: ",Table164[[#This Row],[Brand]]," - ")),IF(Table164[[#This Row],[Model]]="n|a","",CONCATENATE("Model: ",Table164[[#This Row],[Model]]," - ")),IF(Table164[[#This Row],[Serial Number]]="n|a","",CONCATENATE("SN: ",Table164[[#This Row],[Serial Number]]," - ")),IF(Table164[[#This Row],[Processor]]="n|a","",CONCATENATE("Processor: ",Table164[[#This Row],[Processor]]," - ")),IF(Table164[[#This Row],[RAM]]="n|a","",CONCATENATE("RAM: ",Table164[[#This Row],[RAM]]," - ")),IF(Table164[[#This Row],[Storage]]="n|a","",CONCATENATE("Storage: ",Table164[[#This Row],[Storage]]," - ")),IF(Table164[[#This Row],[Color]]="n|a","",CONCATENATE("Color: ",Table164[[#This Row],[Color]]))) -> Laptop - Brand: Acer - Model: Switch Alpha 12 - Color: Black
B12: 2 | C12: ICT Equipment | D12: =CONCATENATE(TEXT(Table164[[#This Row],[Date of Acquisition]],"yyyy")," - ", VLOOKUP(Table164[[#This Row],[Article]],'Data Validation'!$A$2:$B$16,2,FALSE)," - ",TEXT(Table164[[#This Row],[Series Number]],"0000")," - ",TEXT(VLOOKUP(Table164[[#This Row],[Location]],'Data Validation'!$A$20:$B$47,2,FALSE),"00")) -> 2019 - 05 - 03 - 0002 - 01A | E12: Laptop | F12: Asus | G12: S530 | H12: n|a | I12: n|a | J12: n|a | K12: n|a | L12: n|a | M12: Laptop | N12: unit | O12: 63000 | P12: =Table164[[#This Row],[Unit Value]]*Table164[[#This Row],[Qty | PCount]] -> 63000 | Q12: =IF(Table164[[#This Row],[Unit Value]]<=4999,"Low-Value Asset","High-Value Asset") -> High-Value Asset | R12: 1 | S12: 1 | T12: 0 | U12: 0 | V12: 43700 | W12: 001A - Office of the School Division Superintendent | Z12: Unserviceable | AA12: =CONCATENATE(Table164[[#This Row],[Other Description]]," - ",IF(Table164[[#This Row],[Brand]]="n|a","",CONCATENATE("Brand: ",Table164[[#This Row],[Brand]]," - ")),IF(Table164[[#This Row],[Model]]="n|a","",CONCATENATE("Model: ",Table164[[#This Row],[Model]]," - ")),IF(Table164[[#This Row],[Serial Number]]="n|a","",CONCATENATE("SN: ",Table164[[#This Row],[Serial Number]]," - ")),IF(Table164[[#This Row],[Processor]]="n|a","",CONCATENATE("Processor: ",Table164[[#This Row],[Processor]]," - ")),IF(Table164[[#This Row],[RAM]]="n|a","",CONCATENATE("RAM: ",Table164[[#This Row],[RAM]]," - ")),IF(Table164[[#This Row],[Storage]]="n|a","",CONCATENATE("Storage: ",Table164[[#This Row],[Storage]]," - ")),IF(Table164[[#This Row],[Color]]="n|a","",CONCATENATE("Color: ",Table164[[#This Row],[Color]]))) -> Laptop - Brand: Asus - Model: S530 -
B13: 1 | C13: Medical Equipment | D13: =CONCATENATE(TEXT(Table164[[#This Row],[Date of Acquisition]],"yyyy")," - ", VLOOKUP(Table164[[#This Row],[Article]],'Data Validation'!$A$2:$B$16,2,FALSE)," - ",TEXT(Table164[[#This Row],[Series Number]],"0000")," - ",TEXT(VLOOKUP(Table164[[#This Row],[Location]],'Data Validation'!$A$20:$B$47,2,FALSE),"00")) -> 2005 - 05 - 11 - 0001 - 01A | E13: Dental Chair | F13: n|a | G13: n|a | H13: n|a | I13: n|a | J13: n|a | K13: n|a | L13: Red | M13: Dental Chair | N13: unit | O13: 221760.75 | P13: =Table164[[#This Row],[Unit Value]]*Table164[[#This Row],[Qty | PCount]] -> 221760.75 | Q13: =IF(Table164[[#This Row],[Unit Value]]<=4999,"Low-Value Asset","High-Value Asset") -> High-Value Asset | R13: 1 | S13: 1 | T13: 0 | U13: 0 | V13: 38580 | W13: 001A - Office of the School Division Superintendent | X13: - | Y13: - | Z13: Unserviceable | AA13: =CONCATENATE(Table164[[#This Row],[Other Description]]," - ",IF(Table164[[#This Row],[Brand]]="n|a","",CONCATENATE("Brand: ",Table164[[#This Row],[Brand]]," - ")),IF(Table164[[#This Row],[Model]]="n|a","",CONCATENATE("Model: ",Table164[[#This Row],[Model]]," - ")),IF(Table164[[#This Row],[Serial Number]]="n|a","",CONCATENATE("SN: ",Table164[[#This Row],[Serial Number]]," - ")),IF(Table164[[#This Row],[Processor]]="n|a","",CONCATENATE("Processor: ",Table164[[#This Row],[Processor]]," - ")),IF(Table164[[#This Row],[RAM]]="n|a","",CONCATENATE("RAM: ",Table164[[#This Row],[RAM]]," - ")),IF(Table164[[#This Row],[Storage]]="n|a","",CONCATENATE("Storage: ",Table164[[#This Row],[Storage]]," - ")),IF(Table164[[#This Row],[Color]]="n|a","",CONCATENATE("Color: ",Table164[[#This Row],[Color]]))) -> Dental Chair - Color: Red
B14: 2 | C14: Medical Equipment | D14: =CONCATENATE(TEXT(Table164[[#This Row],[Date of Acquisition]],"yyyy")," - ", VLOOKUP(Table164[[#This Row],[Article]],'Data Validation'!$A$2:$B$16,2,FALSE)," - ",TEXT(Table164[[#This Row],[Series Number]],"0000")," - ",TEXT(VLOOKUP(Table164[[#This Row],[Location]],'Data Validation'!$A$20:$B$47,2,FALSE),"00")) -> 2005 - 05 - 11 - 0002 - 01A | E14: Dental Chair Accessories | F14: n|a | G14: n|a | H14: n|a | I14: n|a | J14: n|a | K14: n|a | L14: n|a | M14: Compressor with Attaching Parts | N14: unit | O14: 72650 | P14: =Table164[[#This Row],[Unit Value]]*Table164[[#This Row],[Qty | PCount]] -> 72650 | Q14: =IF(Table164[[#This Row],[Unit Value]]<=4999,"Low-Value Asset","High-Value Asset") -> High-Value Asset | R14: 1 | S14: 1 | T14: 0 | U14: 0 | V14: 38687 | W14: 001A - Office of the School Division Superintendent | X14: - | Y14: - | Z14: Unserviceable | AA14: =CONCATENATE(Table164[[#This Row],[Other Description]]," - ",IF(Table164[[#This Row],[Brand]]="n|a","",CONCATENATE("Brand: ",Table164[[#This Row],[Brand]]," - ")),IF(Table164[[#This Row],[Model]]="n|a","",CONCATENATE("Model: ",Table164[[#This Row],[Model]]," - ")),IF(Table164[[#This Row],[Serial Number]]="n|a","",CONCATENATE("SN: ",Table164[[#This Row],[Serial Number]]," - ")),IF(Table164[[#This Row],[Processor]]="n|a","",CONCATENATE("Processor: ",Table164[[#This Row],[Processor]]," - ")),IF(Table164[[#This Row],[RAM]]="n|a","",CONCATENATE("RAM: ",Table164[[#This Row],[RAM]]," - ")),IF(Table164[[#This Row],[Storage]]="n|a","",CONCATENATE("Storage: ",Table164[[#This Row],[Storage]]," - ")),IF(Table164[[#This Row],[Color]]="n|a","",CONCATENATE("Color: ",Table164[[#This Row],[Color]]))) -> Compressor with Attaching Parts -
B15: 1 | C15: Motor Vehicle | D15: =CONCATENATE(TEXT(Table164[[#This Row],[Date of Acquisition]],"yyyy")," - ", VLOOKUP(Table164[[#This Row],[Article]],'Data Validation'!$A$2:$B$16,2,FALSE)," - ",TEXT(Table164[[#This Row],[Series Number]],"0000")," - ",TEXT(VLOOKUP(Table164[[#This Row],[Location]],'Data Validation'!$A$20:$B$47,2,FALSE),"00")) -> 2007 - 06 - 01 - 0001 - 01A | E15: Revo | F15: Toyota | G15: Revo Wagon 1999 | H15: n|a | I15: n|a | J15: n|a | K15: n|a | L15: Red | M15: Manual Transmission - Gas Fueled - Plate Number: SGB-883 | N15: unit | O15: 335000 | P15: =Table164[[#This Row],[Unit Value]]*Table164[[#This Row],[Qty | PCount]] -> 335000 | Q15: =IF(Table164[[#This Row],[Unit Value]]<=4999,"Low-Value Asset","High-Value Asset") -> High-Value Asset | R15: 1 | S15: 1 | T15: 0 | U15: 0 | V15: 39083 | W15: 001A - Office of the School Division Superintendent | X15: - | Y15: - | Z15: Unserviceable | AA15: =CONCATENATE(Table164[[#This Row],[Other Description]]," - ",IF(Table164[[#This Row],[Brand]]="n|a","",CONCATENATE("Brand: ",Table164[[#This Row],[Brand]]," - ")),IF(Table164[[#This Row],[Model]]="n|a","",CONCATENATE("Model: ",Table164[[#This Row],[Model]]," - ")),IF(Table164[[#This Row],[Serial Number]]="n|a","",CONCATENATE("SN: ",Table164[[#This Row],[Serial Number]]," - ")),IF(Table164[[#This Row],[Processor]]="n|a","",CONCATENATE("Processor: ",Table164[[#This Row],[Processor]]," - ")),IF(Table164[[#This Row],[RAM]]="n|a","",CONCATENATE("RAM: ",Table164[[#This Row],[RAM]]," - ")),IF(Table164[[#This Row],[Storage]]="n|a","",CONCATENATE("Storage: ",Table164[[#This Row],[Storage]]," - ")),IF(Table164[[#This Row],[Color]]="n|a","",CONCATENATE("Color: ",Table164[[#This Row],[Color]]))) -> Manual Transmission - Gas Fueled - Plate Number: SGB-883 - Brand: Toyota - Model: Revo Wagon 1999 - Color: Red
B16: 1 | C16: Office Equipment | D16: =CONCATENATE(TEXT(Table164[[#This Row],[Date of Acquisition]],"yyyy")," - ", VLOOKUP(Table164[[#This Row],[Article]],'Data Validation'!$A$2:$B$16,2,FALSE)," - ",TEXT(Table164[[#This Row],[Series Number]],"0000")," - ",TEXT(VLOOKUP(Table164[[#This Row],[Location]],'Data Validation'!$A$20:$B$47,2,FALSE),"00")) -> 2005 - 05 - 02 - 0001 - 01A | E16: Printing Machine | F16: RISO | G16: KS800 | H16: n|a | I16: n|a | J16: n|a | K16: n|a | L16: White | M16: Risograph Machine | N16: unit | O16: 222000 | P16: =Table164[[#This Row],[Unit Value]]*Table164[[#This Row],[Qty | PCount]] -> 222000 | Q16: =IF(Table164[[#This Row],[Unit Value]]<=4999,"Low-Value Asset","High-Value Asset") -> High-Value Asset | R16: 1 | S16: 1 | T16: 0 | U16: 0 | V16: 38353 | W16: 001A - Office of the School Division Superintendent | X16: - | Y16: - | Z16: Unserviceable | AA16: =CONCATENATE(Table164[[#This Row],[Other Description]]," - ",IF(Table164[[#This Row],[Brand]]="n|a","",CONCATENATE("Brand: ",Table164[[#This Row],[Brand]]," - ")),IF(Table164[[#This Row],[Model]]="n|a","",CONCATENATE("Model: ",Table164[[#This Row],[Model]]," - ")),IF(Table164[[#This Row],[Serial Number]]="n|a","",CONCATENATE("SN: ",Table164[[#This Row],[Serial Number]]," - ")),IF(Table164[[#This Row],[Processor]]="n|a","",CONCATENATE("Processor: ",Table164[[#This Row],[Processor]]," - ")),IF(Table164[[#This Row],[RAM]]="n|a","",CONCATENATE("RAM: ",Table164[[#This Row],[RAM]]," - ")),IF(Table164[[#This Row],[Storage]]="n|a","",CONCATENATE("Storage: ",Table164[[#This Row],[Storage]]," - ")),IF(Table164[[#This Row],[Color]]="n|a","",CONCATENATE("Color: ",Table164[[#This Row],[Color]]))) -> Risograph Machine - Brand: RISO - Model: KS800 - Color: White
B17: 1 | C17: Office Equipment | D17: =CONCATENATE(TEXT(Table164[[#This Row],[Date of Acquisition]],"yyyy")," - ", VLOOKUP(Table164[[#This Row],[Article]],'Data Validation'!$A$2:$B$16,2,FALSE)," - ",TEXT(Table164[[#This Row],[Series Number]],"0000")," - ",TEXT(VLOOKUP(Table164[[#This Row],[Location]],'Data Validation'!$A$20:$B$47,2,FALSE),"00")) -> 2010 - 05 - 02 - 0001 - 01A | E17: Printing Machine | F17: Canon | G17: DQT-04749 | H17: n|a | I17: n|a | J17: n|a | K17: n|a | L17: n|a | M17: Canon Copier | N17: unit | O17: 76000 | P17: =Table164[[#This Row],[Unit Value]]*Table164[[#This Row],[Qty | PCount]] -> 76000 | Q17: =IF(Table164[[#This Row],[Unit Value]]<=4999,"Low-Value Asset","High-Value Asset") -> High-Value Asset | R17: 1 | S17: 1 | T17: 0 | U17: 0 | V17: 40466 | W17: 001A - Office of the School Division Superintendent | X17: - | Y17: - | Z17: Unserviceable | AA17: =CONCATENATE(Table164[[#This Row],[Other Description]]," - ",IF(Table164[[#This Row],[Brand]]="n|a","",CONCATENATE("Brand: ",Table164[[#This Row],[Brand]]," - ")),IF(Table164[[#This Row],[Model]]="n|a","",CONCATENATE("Model: ",Table164[[#This Row],[Model]]," - ")),IF(Table164[[#This Row],[Serial Number]]="n|a","",CONCATENATE("SN: ",Table164[[#This Row],[Serial Number]]," - ")),IF(Table164[[#This Row],[Processor]]="n|a","",CONCATENATE("Processor: ",Table164[[#This Row],[Processor]]," - ")),IF(Table164[[#This Row],[RAM]]="n|a","",CONCATENATE("RAM: ",Table164[[#This Row],[RAM]]," - ")),IF(Table164[[#This Row],[Storage]]="n|a","",CONCATENATE("Storage: ",Table164[[#This Row],[Storage]]," - ")),IF(Table164[[#This Row],[Color]]="n|a","",CONCATENATE("Color: ",Table164[[#This Row],[Color]]))) -> Canon Copier - Brand: Canon - Model: DQT-04749 -
B18: 1 | C18: Office Equipment | D18: =CONCATENATE(TEXT(Table164[[#This Row],[Date of Acquisition]],"yyyy")," - ", VLOOKUP(Table164[[#This Row],[Article]],'Data Validation'!$A$2:$B$16,2,FALSE)," - ",TEXT(Table164[[#This Row],[Series Number]],"0000")," - ",TEXT(VLOOKUP(Table164[[#This Row],[Location]],'Data Validation'!$A$20:$B$47,2,FALSE),"00")) -> 2016 - 05 - 02 - 0001 - 01A | E18: Intercom | F18: n|a | G18: n|a | H18: n|a | I18: n|a | J18: n|a | K18: n|a | L18: n|a | M18: Intercom | N18: unit | O18: 56330 | P18: =Table164[[#This Row],[Unit Value]]*Table164[[#This Row],[Qty | PCount]] -> 56330 | Q18: =IF(Table164[[#This Row],[Unit Value]]<=4999,"Low-Value Asset","High-Value Asset") -> High-Value Asset | R18: 1 | S18: 1 | T18: 0 | U18: 0 | V18: 42725 | W18: 001A - Office of the School Division Superintendent | X18: - | Y18: - | Z18: Unserviceable | AA18: =CONCATENATE(Table164[[#This Row],[Other Description]]," - ",IF(Table164[[#This Row],[Brand]]="n|a","",CONCATENATE("Brand: ",Table164[[#This Row],[Brand]]," - ")),IF(Table164[[#This Row],[Model]]="n|a","",CONCATENATE("Model: ",Table164[[#This Row],[Model]]," - ")),IF(Table164[[#This Row],[Serial Number]]="n|a","",CONCATENATE("SN: ",Table164[[#This Row],[Serial Number]]," - ")),IF(Table164[[#This Row],[Processor]]="n|a","",CONCATENATE("Processor: ",Table164[[#This Row],[Processor]]," - ")),IF(Table164[[#This Row],[RAM]]="n|a","",CONCATENATE("RAM: ",Table164[[#This Row],[RAM]]," - ")),IF(Table164[[#This Row],[Storage]]="n|a","",CONCATENATE("Storage: ",Table164[[#This Row],[Storage]]," - ")),IF(Table164[[#This Row],[Color]]="n|a","",CONCATENATE("Color: ",Table164[[#This Row],[Color]]))) -> Intercom -
B19: 1 | C19: Other PPE | D19: =CONCATENATE(TEXT(Table164[[#This Row],[Date of Acquisition]],"yyyy")," - ", VLOOKUP(Table164[[#This Row],[Article]],'Data Validation'!$A$2:$B$16,2,FALSE)," - ",TEXT(Table164[[#This Row],[Series Number]],"0000")," - ",TEXT(VLOOKUP(Table164[[#This Row],[Location]],'Data Validation'!$A$20:$B$47,2,FALSE),"00")) -> 1997 - 00 - 00 - 0001 - 01A | E19: Pumping Stations,& Conduits | F19: n|a | G19: n|a | H19: n|a | I19: n|a | J19: n|a | K19: n|a | L19: n|a | M19: 'Pumping Stations,& Conduits | N19: unit | O19: 156353.35 | P19: =Table164[[#This Row],[Unit Value]]*Table164[[#This Row],[Qty | PCount]] -> 156353.35 | Q19: =IF(Table164[[#This Row],[Unit Value]]<=4999,"Low-Value Asset","High-Value Asset") -> High-Value Asset | R19: 1 | S19: 1 | T19: 0 | U19: 0 | V19: 35582 | W19: 001A - Office of the School Division Superintendent | X19: - | Y19: - | Z19: Unserviceable | AA19: =CONCATENATE(Table164[[#This Row],[Other Description]]," - ",IF(Table164[[#This Row],[Brand]]="n|a","",CONCATENATE("Brand: ",Table164[[#This Row],[Brand]]," - ")),IF(Table164[[#This Row],[Model]]="n|a","",CONCATENATE("Model: ",Table164[[#This Row],[Model]]," - ")),IF(Table164[[#This Row],[Serial Number]]="n|a","",CONCATENATE("SN: ",Table164[[#This Row],[Serial Number]]," - ")),IF(Table164[[#This Row],[Processor]]="n|a","",CONCATENATE("Processor: ",Table164[[#This Row],[Processor]]," - ")),IF(Table164[[#This Row],[RAM]]="n|a","",CONCATENATE("RAM: ",Table164[[#This Row],[RAM]]," - ")),IF(Table164[[#This Row],[Storage]]="n|a","",CONCATENATE("Storage: ",Table164[[#This Row],[Storage]]," - ")),IF(Table164[[#This Row],[Color]]="n|a","",CONCATENATE("Color: ",Table164[[#This Row],[Color]]))) -> 'Pumping Stations,& Conduits -
D20: =CONCATENATE(TEXT(Table164[[#This Row],[Date of Acquisition]],"yyyy")," - ", VLOOKUP(Table164[[#This Row],[Article]],'Data Validation'!$A$2:$B$16,2,FALSE)," - ",TEXT(Table164[[#This Row],[Series Number]],"0000")," - ",TEXT(VLOOKUP(Table164[[#This Row],[Location]],'Data Validation'!$A$20:$B$47,2,FALSE),"00")) -> #N/A | P20: =Table164[[#This Row],[Unit Value]]*Table164[[#This Row],[Qty | PCount]] -> 0 | Q20: =IF(Table164[[#This Row],[Unit Value]]<=4999,"Low-Value Asset","High-Value Asset") -> Low-Value Asset | Z20: Unserviceable | AA20: =CONCATENATE(Table164[[#This Row],[Other Description]]," - ",IF(Table164[[#This Row],[Brand]]="n|a","",CONCATENATE("Brand: ",Table164[[#This Row],[Brand]]," - ")),IF(Table164[[#This Row],[Model]]="n|a","",CONCATENATE("Model: ",Table164[[#This Row],[Model]]," - ")),IF(Table164[[#This Row],[Serial Number]]="n|a","",CONCATENATE("SN: ",Table164[[#This Row],[Serial Number]]," - ")),IF(Table164[[#This Row],[Processor]]="n|a","",CONCATENATE("Processor: ",Table164[[#This Row],[Processor]]," - ")),IF(Table164[[#This Row],[RAM]]="n|a","",CONCATENATE("RAM: ",Table164[[#This Row],[RAM]]," - ")),IF(Table164[[#This Row],[Storage]]="n|a","",CONCATENATE("Storage: ",Table164[[#This Row],[Storage]]," - ")),IF(Table164[[#This Row],[Color]]="n|a","",CONCATENATE("Color: ",Table164[[#This Row],[Color]]))) -> - Brand: - Model: - SN: - Processor: - RAM: - Storage: - Color:
D21: =CONCATENATE(TEXT(Table164[[#This Row],[Date of Acquisition]],"yyyy")," - ", VLOOKUP(Table164[[#This Row],[Article]],'Data Validation'!$A$2:$B$16,2,FALSE)," - ",TEXT(Table164[[#This Row],[Series Number]],"0000")," - ",TEXT(VLOOKUP(Table164[[#This Row],[Location]],'Data Validation'!$A$20:$B$47,2,FALSE),"00")) -> #N/A | P21: =Table164[[#This Row],[Unit Value]]*Table164[[#This Row],[Qty | PCount]] -> 0 | Q21: =IF(Table164[[#This Row],[Unit Value]]<=4999,"Low-Value Asset","High-Value Asset") -> Low-Value Asset | Z21: Unserviceable | AA21: =CONCATENATE(Table164[[#This Row],[Other Description]]," - ",IF(Table164[[#This Row],[Brand]]="n|a","",CONCATENATE("Brand: ",Table164[[#This Row],[Brand]]," - ")),IF(Table164[[#This Row],[Model]]="n|a","",CONCATENATE("Model: ",Table164[[#This Row],[Model]]," - ")),IF(Table164[[#This Row],[Serial Number]]="n|a","",CONCATENATE("SN: ",Table164[[#This Row],[Serial Number]]," - ")),IF(Table164[[#This Row],[Processor]]="n|a","",CONCATENATE("Processor: ",Table164[[#This Row],[Processor]]," - ")),IF(Table164[[#This Row],[RAM]]="n|a","",CONCATENATE("RAM: ",Table164[[#This Row],[RAM]]," - ")),IF(Table164[[#This Row],[Storage]]="n|a","",CONCATENATE("Storage: ",Table164[[#This Row],[Storage]]," - ")),IF(Table164[[#This Row],[Color]]="n|a","",CONCATENATE("Color: ",Table164[[#This Row],[Color]]))) -> - Brand: - Model: - SN: - Processor: - RAM: - Storage: - Color:
D22: =CONCATENATE(TEXT(Table164[[#This Row],[Date of Acquisition]],"yyyy")," - ", VLOOKUP(Table164[[#This Row],[Article]],'Data Validation'!$A$2:$B$16,2,FALSE)," - ",TEXT(Table164[[#This Row],[Series Number]],"0000")," - ",TEXT(VLOOKUP(Table164[[#This Row],[Location]],'Data Validation'!$A$20:$B$47,2,FALSE),"00")) -> #N/A | P22: =Table164[[#This Row],[Unit Value]]*Table164[[#This Row],[Qty | PCount]] -> 0 | Q22: =IF(Table164[[#This Row],[Unit Value]]<=4999,"Low-Value Asset","High-Value Asset") -> Low-Value Asset | Z22: Unserviceable | AA22: =CONCATENATE(Table164[[#This Row],[Other Description]]," - ",IF(Table164[[#This Row],[Brand]]="n|a","",CONCATENATE("Brand: ",Table164[[#This Row],[Brand]]," - ")),IF(Table164[[#This Row],[Model]]="n|a","",CONCATENATE("Model: ",Table164[[#This Row],[Model]]," - ")),IF(Table164[[#This Row],[Serial Number]]="n|a","",CONCATENATE("SN: ",Table164[[#This Row],[Serial Number]]," - ")),IF(Table164[[#This Row],[Processor]]="n|a","",CONCATENATE("Processor: ",Table164[[#This Row],[Processor]]," - ")),IF(Table164[[#This Row],[RAM]]="n|a","",CONCATENATE("RAM: ",Table164[[#This Row],[RAM]]," - ")),IF(Table164[[#This Row],[Storage]]="n|a","",CONCATENATE("Storage: ",Table164[[#This Row],[Storage]]," - ")),IF(Table164[[#This Row],[Color]]="n|a","",CONCATENATE("Color: ",Table164[[#This Row],[Color]]))) -> - Brand: - Model: - SN: - Processor: - RAM: - Storage: - Color:
D23: =CONCATENATE(TEXT(Table164[[#This Row],[Date of Acquisition]],"yyyy")," - ", VLOOKUP(Table164[[#This Row],[Article]],'Data Validation'!$A$2:$B$16,2,FALSE)," - ",TEXT(Table164[[#This Row],[Series Number]],"0000")," - ",TEXT(VLOOKUP(Table164[[#This Row],[Location]],'Data Validation'!$A$20:$B$47,2,FALSE),"00")) -> #N/A | P23: =Table164[[#This Row],[Unit Value]]*Table164[[#This Row],[Qty | PCount]] -> 0 | Q23: =IF(Table164[[#This Row],[Unit Value]]<=4999,"Low-Value Asset","High-Value Asset") -> Low-Value Asset | Z23: Unserviceable | AA23: =CONCATENATE(Table164[[#This Row],[Other Description]]," - ",IF(Table164[[#This Row],[Brand]]="n|a","",CONCATENATE("Brand: ",Table164[[#This Row],[Brand]]," - ")),IF(Table164[[#This Row],[Model]]="n|a","",CONCATENATE("Model: ",Table164[[#This Row],[Model]]," - ")),IF(Table164[[#This Row],[Serial Number]]="n|a","",CONCATENATE("SN: ",Table164[[#This Row],[Serial Number]]," - ")),IF(Table164[[#This Row],[Processor]]="n|a","",CONCATENATE("Processor: ",Table164[[#This Row],[Processor]]," - ")),IF(Table164[[#This Row],[RAM]]="n|a","",CONCATENATE("RAM: ",Table164[[#This Row],[RAM]]," - ")),IF(Table164[[#This Row],[Storage]]="n|a","",CONCATENATE("Storage: ",Table164[[#This Row],[Storage]]," - ")),IF(Table164[[#This Row],[Color]]="n|a","",CONCATENATE("Color: ",Table164[[#This Row],[Color]]))) -> - Brand: - Model: - SN: - Processor: - RAM: - Storage: - Color:
D24: =CONCATENATE(TEXT(Table164[[#This Row],[Date of Acquisition]],"yyyy")," - ", VLOOKUP(Table164[[#This Row],[Article]],'Data Validation'!$A$2:$B$16,2,FALSE)," - ",TEXT(Table164[[#This Row],[Series Number]],"0000")," - ",TEXT(VLOOKUP(Table164[[#This Row],[Location]],'Data Validation'!$A$20:$B$47,2,FALSE),"00")) -> #N/A | P24: =Table164[[#This Row],[Unit Value]]*Table164[[#This Row],[Qty | PCount]] -> 0 | Q24: =IF(Table164[[#This Row],[Unit Value]]<=4999,"Low-Value Asset","High-Value Asset") -> Low-Value Asset | Z24: Unserviceable | AA24: =CONCATENATE(Table164[[#This Row],[Other Description]]," - ",IF(Table164[[#This Row],[Brand]]="n|a","",CONCATENATE("Brand: ",Table164[[#This Row],[Brand]]," - ")),IF(Table164[[#This Row],[Model]]="n|a","",CONCATENATE("Model: ",Table164[[#This Row],[Model]]," - ")),IF(Table164[[#This Row],[Serial Number]]="n|a","",CONCATENATE("SN: ",Table164[[#This Row],[Serial Number]]," - ")),IF(Table164[[#This Row],[Processor]]="n|a","",CONCATENATE("Processor: ",Table164[[#This Row],[Processor]]," - ")),IF(Table164[[#This Row],[RAM]]="n|a","",CONCATENATE("RAM: ",Table164[[#This Row],[RAM]]," - ")),IF(Table164[[#This Row],[Storage]]="n|a","",CONCATENATE("Storage: ",Table164[[#This Row],[Storage]]," - ")),IF(Table164[[#This Row],[Color]]="n|a","",CONCATENATE("Color: ",Table164[[#This Row],[Color]]))) -> - Brand: - Model: - SN: - Processor: - RAM: - Storage: - Color:
D25: =CONCATENATE(TEXT(Table164[[#This Row],[Date of Acquisition]],"yyyy")," - ", VLOOKUP(Table164[[#This Row],[Article]],'Data Validation'!$A$2:$B$16,2,FALSE)," - ",TEXT(Table164[[#This Row],[Series Number]],"0000")," - ",TEXT(VLOOKUP(Table164[[#This Row],[Location]],'Data Validation'!$A$20:$B$47,2,FALSE),"00")) -> #N/A | P25: =Table164[[#This Row],[Unit Value]]*Table164[[#This Row],[Qty | PCount]] -> 0 | Q25: =IF(Table164[[#This Row],[Unit Value]]<=4999,"Low-Value Asset","High-Value Asset") -> Low-Value Asset | Z25: Unserviceable | AA25: =CONCATENATE(Table164[[#This Row],[Other Description]]," - ",IF(Table164[[#This Row],[Brand]]="n|a","",CONCATENATE("Brand: ",Table164[[#This Row],[Brand]]," - ")),IF(Table164[[#This Row],[Model]]="n|a","",CONCATENATE("Model: ",Table164[[#This Row],[Model]]," - ")),IF(Table164[[#This Row],[Serial Number]]="n|a","",CONCATENATE("SN: ",Table164[[#This Row],[Serial Number]]," - ")),IF(Table164[[#This Row],[Processor]]="n|a","",CONCATENATE("Processor: ",Table164[[#This Row],[Processor]]," - ")),IF(Table164[[#This Row],[RAM]]="n|a","",CONCATENATE("RAM: ",Table164[[#This Row],[RAM]]," - ")),IF(Table164[[#This Row],[Storage]]="n|a","",CONCATENATE("Storage: ",Table164[[#This Row],[Storage]]," - ")),IF(Table164[[#This Row],[Color]]="n|a","",CONCATENATE("Color: ",Table164[[#This Row],[Color]]))) -> - Brand: - Model: - SN: - Processor: - RAM: - Storage: - Color:
D26: =CONCATENATE(TEXT(Table164[[#This Row],[Date of Acquisition]],"yyyy")," - ", VLOOKUP(Table164[[#This Row],[Article]],'Data Validation'!$A$2:$B$16,2,FALSE)," - ",TEXT(Table164[[#This Row],[Series Number]],"0000")," - ",TEXT(VLOOKUP(Table164[[#This Row],[Location]],'Data Validation'!$A$20:$B$47,2,FALSE),"00")) -> #N/A | P26: =Table164[[#This Row],[Unit Value]]*Table164[[#This Row],[Qty | PCount]] -> 0 | Q26: =IF(Table164[[#This Row],[Unit Value]]<=4999,"Low-Value Asset","High-Value Asset") -> Low-Value Asset | Z26: Unserviceable | AA26: =CONCATENATE(Table164[[#This Row],[Other Description]]," - ",IF(Table164[[#This Row],[Brand]]="n|a","",CONCATENATE("Brand: ",Table164[[#This Row],[Brand]]," - ")),IF(Table164[[#This Row],[Model]]="n|a","",CONCATENATE("Model: ",Table164[[#This Row],[Model]]," - ")),IF(Table164[[#This Row],[Serial Number]]="n|a","",CONCATENATE("SN: ",Table164[[#This Row],[Serial Number]]," - ")),IF(Table164[[#This Row],[Processor]]="n|a","",CONCATENATE("Processor: ",Table164[[#This Row],[Processor]]," - ")),IF(Table164[[#This Row],[RAM]]="n|a","",CONCATENATE("RAM: ",Table164[[#This Row],[RAM]]," - ")),IF(Table164[[#This Row],[Storage]]="n|a","",CONCATENATE("Storage: ",Table164[[#This Row],[Storage]]," - ")),IF(Table164[[#This Row],[Color]]="n|a","",CONCATENATE("Color: ",Table164[[#This Row],[Color]]))) -> - Brand: - Model: - SN: - Processor: - RAM: - Storage: - Color:
D27: =CONCATENATE(TEXT(Table164[[#This Row],[Date of Acquisition]],"yyyy")," - ", VLOOKUP(Table164[[#This Row],[Article]],'Data Validation'!$A$2:$B$16,2,FALSE)," - ",TEXT(Table164[[#This Row],[Series Number]],"0000")," - ",TEXT(VLOOKUP(Table164[[#This Row],[Location]],'Data Validation'!$A$20:$B$47,2,FALSE),"00")) -> #N/A | P27: =Table164[[#This Row],[Unit Value]]*Table164[[#This Row],[Qty | PCount]] -> 0 | Q27: =IF(Table164[[#This Row],[Unit Value]]<=4999,"Low-Value Asset","High-Value Asset") -> Low-Value Asset | Z27: Unserviceable | AA27: =CONCATENATE(Table164[[#This Row],[Other Description]]," - ",IF(Table164[[#This Row],[Brand]]="n|a","",CONCATENATE("Brand: ",Table164[[#This Row],[Brand]]," - ")),IF(Table164[[#This Row],[Model]]="n|a","",CONCATENATE("Model: ",Table164[[#This Row],[Model]]," - ")),IF(Table164[[#This Row],[Serial Number]]="n|a","",CONCATENATE("SN: ",Table164[[#This Row],[Serial Number]]," - ")),IF(Table164[[#This Row],[Processor]]="n|a","",CONCATENATE("Processor: ",Table164[[#This Row],[Processor]]," - ")),IF(Table164[[#This Row],[RAM]]="n|a","",CONCATENATE("RAM: ",Table164[[#This Row],[RAM]]," - ")),IF(Table164[[#This Row],[Storage]]="n|a","",CONCATENATE("Storage: ",Table164[[#This Row],[Storage]]," - ")),IF(Table164[[#This Row],[Color]]="n|a","",CONCATENATE("Color: ",Table164[[#This Row],[Color]]))) -> - Brand: - Model: - SN: - Processor: - RAM: - Storage: - Color:
D28: =CONCATENATE(TEXT(Table164[[#This Row],[Date of Acquisition]],"yyyy")," - ", VLOOKUP(Table164[[#This Row],[Article]],'Data Validation'!$A$2:$B$16,2,FALSE)," - ",TEXT(Table164[[#This Row],[Series Number]],"0000")," - ",TEXT(VLOOKUP(Table164[[#This Row],[Location]],'Data Validation'!$A$20:$B$47,2,FALSE),"00")) -> #N/A | P28: =Table164[[#This Row],[Unit Value]]*Table164[[#This Row],[Qty | PCount]] -> 0 | Q28: =IF(Table164[[#This Row],[Unit Value]]<=4999,"Low-Value Asset","High-Value Asset") -> Low-Value Asset | Z28: Unserviceable | AA28: =CONCATENATE(Table164[[#This Row],[Other Description]]," - ",IF(Table164[[#This Row],[Brand]]="n|a","",CONCATENATE("Brand: ",Table164[[#This Row],[Brand]]," - ")),IF(Table164[[#This Row],[Model]]="n|a","",CONCATENATE("Model: ",Table164[[#This Row],[Model]]," - ")),IF(Table164[[#This Row],[Serial Number]]="n|a","",CONCATENATE("SN: ",Table164[[#This Row],[Serial Number]]," - ")),IF(Table164[[#This Row],[Processor]]="n|a","",CONCATENATE("Processor: ",Table164[[#This Row],[Processor]]," - ")),IF(Table164[[#This Row],[RAM]]="n|a","",CONCATENATE("RAM: ",Table164[[#This Row],[RAM]]," - ")),IF(Table164[[#This Row],[Storage]]="n|a","",CONCATENATE("Storage: ",Table164[[#This Row],[Storage]]," - ")),IF(Table164[[#This Row],[Color]]="n|a","",CONCATENATE("Color: ",Table164[[#This Row],[Color]]))) -> - Brand: - Model: - SN: - Processor: - RAM: - Storage: - Color:
D29: =CONCATENATE(TEXT(Table164[[#This Row],[Date of Acquisition]],"yyyy")," - ", VLOOKUP(Table164[[#This Row],[Article]],'Data Validation'!$A$2:$B$16,2,FALSE)," - ",TEXT(Table164[[#This Row],[Series Number]],"0000")," - ",TEXT(VLOOKUP(Table164[[#This Row],[Location]],'Data Validation'!$A$20:$B$47,2,FALSE),"00")) -> #N/A | P29: =Table164[[#This Row],[Unit Value]]*Table164[[#This Row],[Qty | PCount]] -> 0 | Q29: =IF(Table164[[#This Row],[Unit Value]]<=4999,"Low-Value Asset","High-Value Asset") -> Low-Value Asset | Z29: Unserviceable | AA29: =CONCATENATE(Table164[[#This Row],[Other Description]]," - ",IF(Table164[[#This Row],[Brand]]="n|a","",CONCATENATE("Brand: ",Table164[[#This Row],[Brand]]," - ")),IF(Table164[[#This Row],[Model]]="n|a","",CONCATENATE("Model: ",Table164[[#This Row],[Model]]," - ")),IF(Table164[[#This Row],[Serial Number]]="n|a","",CONCATENATE("SN: ",Table164[[#This Row],[Serial Number]]," - ")),IF(Table164[[#This Row],[Processor]]="n|a","",CONCATENATE("Processor: ",Table164[[#This Row],[Processor]]," - ")),IF(Table164[[#This Row],[RAM]]="n|a","",CONCATENATE("RAM: ",Table164[[#This Row],[RAM]]," - ")),IF(Table164[[#This Row],[Storage]]="n|a","",CONCATENATE("Storage: ",Table164[[#This Row],[Storage]]," - ")),IF(Table164[[#This Row],[Color]]="n|a","",CONCATENATE("Color: ",Table164[[#This Row],[Color]]))) -> - Brand: - Model: - SN: - Processor: - RAM: - Storage: - Color:
D30: =CONCATENATE(TEXT(Table164[[#This Row],[Date of Acquisition]],"yyyy")," - ", VLOOKUP(Table164[[#This Row],[Article]],'Data Validation'!$A$2:$B$16,2,FALSE)," - ",TEXT(Table164[[#This Row],[Series Number]],"0000")," - ",TEXT(VLOOKUP(Table164[[#This Row],[Location]],'Data Validation'!$A$20:$B$47,2,FALSE),"00")) -> #N/A | P30: =Table164[[#This Row],[Unit Value]]*Table164[[#This Row],[Qty | PCount]] -> 0 | Q30: =IF(Table164[[#This Row],[Unit Value]]<=4999,"Low-Value Asset","High-Value Asset") -> Low-Value Asset | Z30: Unserviceable | AA30: =CONCATENATE(Table164[[#This Row],[Other Description]]," - ",IF(Table164[[#This Row],[Brand]]="n|a","",CONCATENATE("Brand: ",Table164[[#This Row],[Brand]]," - ")),IF(Table164[[#This Row],[Model]]="n|a","",CONCATENATE("Model: ",Table164[[#This Row],[Model]]," - ")),IF(Table164[[#This Row],[Serial Number]]="n|a","",CONCATENATE("SN: ",Table164[[#This Row],[Serial Number]]," - ")),IF(Table164[[#This Row],[Processor]]="n|a","",CONCATENATE("Processor: ",Table164[[#This Row],[Processor]]," - ")),IF(Table164[[#This Row],[RAM]]="n|a","",CONCATENATE("RAM: ",Table164[[#This Row],[RAM]]," - ")),IF(Table164[[#This Row],[Storage]]="n|a","",CONCATENATE("Storage: ",Table164[[#This Row],[Storage]]," - ")),IF(Table164[[#This Row],[Color]]="n|a","",CONCATENATE("Color: ",Table164[[#This Row],[Color]]))) -> - Brand: - Model: - SN: - Processor: - RAM: - Storage: - Color:
D31: =CONCATENATE(TEXT(Table164[[#This Row],[Date of Acquisition]],"yyyy")," - ", VLOOKUP(Table164[[#This Row],[Article]],'Data Validation'!$A$2:$B$16,2,FALSE)," - ",TEXT(Table164[[#This Row],[Series Number]],"0000")," - ",TEXT(VLOOKUP(Table164[[#This Row],[Location]],'Data Validation'!$A$20:$B$47,2,FALSE),"00")) -> #N/A | P31: =Table164[[#This Row],[Unit Value]]*Table164[[#This Row],[Qty | PCount]] -> 0 | Q31: =IF(Table164[[#This Row],[Unit Value]]<=4999,"Low-Value Asset","High-Value Asset") -> Low-Value Asset | Z31: Unserviceable | AA31: =CONCATENATE(Table164[[#This Row],[Other Description]]," - ",IF(Table164[[#This Row],[Brand]]="n|a","",CONCATENATE("Brand: ",Table164[[#This Row],[Brand]]," - ")),IF(Table164[[#This Row],[Model]]="n|a","",CONCATENATE("Model: ",Table164[[#This Row],[Model]]," - ")),IF(Table164[[#This Row],[Serial Number]]="n|a","",CONCATENATE("SN: ",Table164[[#This Row],[Serial Number]]," - ")),IF(Table164[[#This Row],[Processor]]="n|a","",CONCATENATE("Processor: ",Table164[[#This Row],[Processor]]," - ")),IF(Table164[[#This Row],[RAM]]="n|a","",CONCATENATE("RAM: ",Table164[[#This Row],[RAM]]," - ")),IF(Table164[[#This Row],[Storage]]="n|a","",CONCATENATE("Storage: ",Table164[[#This Row],[Storage]]," - ")),IF(Table164[[#This Row],[Color]]="n|a","",CONCATENATE("Color: ",Table164[[#This Row],[Color]]))) -> - Brand: - Model: - SN: - Processor: - RAM: - Storage: - Color:
... D33: =CONCATENATE(TEXT(Table164[[#This Row],[Date of Acquisition]],"yyyy")," - ", VLOOKUP(Table164[[#This Row],[Article]],'Data Validation'!$A$2:$B$16,2,FALSE)," - ",TEXT(Table164[[#This Row],[Series Number]],"0000")," - ",TEXT(VLOOKUP(Table164[[#This Row],[Location]],'Data Validation'!$A$20:$B$47,2,FALSE),"00")) -> #N/A | P33: =Table164[[#This Row],[Unit Value]]*Table164[[#This Row],[Qty | PCount]] -> 0 | Q33: =IF(Table164[[#This Row],[Unit Value]]<=4999,"Low-Value Asset","High-Value Asset") -> Low-Value Asset | Z33: Unserviceable | AA33: =CONCATENATE(Table164[[#This Row],[Other Description]]," - ",IF(Table164[[#This Row],[Brand]]="n|a","",CONCATENATE("Brand: ",Table164[[#This Row],[Brand]]," - ")),IF(Table164[[#This Row],[Model]]="n|a","",CONCATENATE("Model: ",Table164[[#This Row],[Model]]," - ")),IF(Table164[[#This Row],[Serial Number]]="n|a","",CONCATENATE("SN: ",Table164[[#This Row],[Serial Number]]," - ")),IF(Table164[[#This Row],[Processor]]="n|a","",CONCATENATE("Processor: ",Table164[[#This Row],[Processor]]," - ")),IF(Table164[[#This Row],[RAM]]="n|a","",CONCATENATE("RAM: ",Table164[[#This Row],[RAM]]," - ")),IF(Table164[[#This Row],[Storage]]="n|a","",CONCATENATE("Storage: ",Table164[[#This Row],[Storage]]," - ")),IF(Table164[[#This Row],[Color]]="n|a","",CONCATENATE("Color: ",Table164[[#This Row],[Color]]))) -> - Brand: - Model: - SN: - Processor: - RAM: - Storage: - Color:
D34: =CONCATENATE(TEXT(Table164[[#This Row],[Date of Acquisition]],"yyyy")," - ", VLOOKUP(Table164[[#This Row],[Article]],'Data Validation'!$A$2:$B$16,2,FALSE)," - ",TEXT(Table164[[#This Row],[Series Number]],"0000")," - ",TEXT(VLOOKUP(Table164[[#This Row],[Location]],'Data Validation'!$A$20:$B$47,2,FALSE),"00")) -> #N/A | P34: =Table164[[#This Row],[Unit Value]]*Table164[[#This Row],[Qty | PCount]] -> 0 | Q34: =IF(Table164[[#This Row],[Unit Value]]<=4999,"Low-Value Asset","High-Value Asset") -> Low-Value Asset | AA34: =CONCATENATE(Table164[[#This Row],[Other Description]]," - ",IF(Table164[[#This Row],[Brand]]="n|a","",CONCATENATE("Brand: ",Table164[[#This Row],[Brand]]," - ")),IF(Table164[[#This Row],[Model]]="n|a","",CONCATENATE("Model: ",Table164[[#This Row],[Model]]," - ")),IF(Table164[[#This Row],[Serial Number]]="n|a","",CONCATENATE("SN: ",Table164[[#This Row],[Serial Number]]," - ")),IF(Table164[[#This Row],[Processor]]="n|a","",CONCATENATE("Processor: ",Table164[[#This Row],[Processor]]," - ")),IF(Table164[[#This Row],[RAM]]="n|a","",CONCATENATE("RAM: ",Table164[[#This Row],[RAM]]," - ")),IF(Table164[[#This Row],[Storage]]="n|a","",CONCATENATE("Storage: ",Table164[[#This Row],[Storage]]," - ")),IF(Table164[[#This Row],[Color]]="n|a","",CONCATENATE("Color: ",Table164[[#This Row],[Color]]))) -> - Brand: - Model: - SN: - Processor: - RAM: - Storage: - Color:
D35: =CONCATENATE(TEXT(Table164[[#This Row],[Date of Acquisition]],"yyyy")," - ", VLOOKUP(Table164[[#This Row],[Article]],'Data Validation'!$A$2:$B$16,2,FALSE)," - ",TEXT(Table164[[#This Row],[Series Number]],"0000")," - ",TEXT(VLOOKUP(Table164[[#This Row],[Location]],'Data Validation'!$A$20:$B$47,2,FALSE),"00")) -> #N/A | P35: =Table164[[#This Row],[Unit Value]]*Table164[[#This Row],[Qty | PCount]] -> 0 | Q35: =IF(Table164[[#This Row],[Unit Value]]<=4999,"Low-Value Asset","High-Value Asset") -> Low-Value Asset | AA35: =CONCATENATE(Table164[[#This Row],[Other Description]]," - ",IF(Table164[[#This Row],[Brand]]="n|a","",CONCATENATE("Brand: ",Table164[[#This Row],[Brand]]," - ")),IF(Table164[[#This Row],[Model]]="n|a","",CONCATENATE("Model: ",Table164[[#This Row],[Model]]," - ")),IF(Table164[[#This Row],[Serial Number]]="n|a","",CONCATENATE("SN: ",Table164[[#This Row],[Serial Number]]," - ")),IF(Table164[[#This Row],[Processor]]="n|a","",CONCATENATE("Processor: ",Table164[[#This Row],[Processor]]," - ")),IF(Table164[[#This Row],[RAM]]="n|a","",CONCATENATE("RAM: ",Table164[[#This Row],[RAM]]," - ")),IF(Table164[[#This Row],[Storage]]="n|a","",CONCATENATE("Storage: ",Table164[[#This Row],[Storage]]," - ")),IF(Table164[[#This Row],[Color]]="n|a","",CONCATENATE("Color: ",Table164[[#This Row],[Color]]))) -> - Brand: - Model: - SN: - Processor: - RAM: - Storage: - Color:
D36: =CONCATENATE(TEXT(Table164[[#This Row],[Date of Acquisition]],"yyyy")," - ", VLOOKUP(Table164[[#This Row],[Article]],'Data Validation'!$A$2:$B$16,2,FALSE)," - ",TEXT(Table164[[#This Row],[Series Number]],"0000")," - ",TEXT(VLOOKUP(Table164[[#This Row],[Location]],'Data Validation'!$A$20:$B$47,2,FALSE),"00")) -> #N/A | P36: =Table164[[#This Row],[Unit Value]]*Table164[[#This Row],[Qty | PCount]] -> 0 | Q36: =IF(Table164[[#This Row],[Unit Value]]<=4999,"Low-Value Asset","High-Value Asset") -> Low-Value Asset | AA36: =CONCATENATE(Table164[[#This Row],[Other Description]]," - ",IF(Table164[[#This Row],[Brand]]="n|a","",CONCATENATE("Brand: ",Table164[[#This Row],[Brand]]," - ")),IF(Table164[[#This Row],[Model]]="n|a","",CONCATENATE("Model: ",Table164[[#This Row],[Model]]," - ")),IF(Table164[[#This Row],[Serial Number]]="n|a","",CONCATENATE("SN: ",Table164[[#This Row],[Serial Number]]," - ")),IF(Table164[[#This Row],[Processor]]="n|a","",CONCATENATE("Processor: ",Table164[[#This Row],[Processor]]," - ")),IF(Table164[[#This Row],[RAM]]="n|a","",CONCATENATE("RAM: ",Table164[[#This Row],[RAM]]," - ")),IF(Table164[[#This Row],[Storage]]="n|a","",CONCATENATE("Storage: ",Table164[[#This Row],[Storage]]," - ")),IF(Table164[[#This Row],[Color]]="n|a","",CONCATENATE("Color: ",Table164[[#This Row],[Color]]))) -> - Brand: - Model: - SN: - Processor: - RAM: - Storage: - Color:
D37: =CONCATENATE(TEXT(Table164[[#This Row],[Date of Acquisition]],"yyyy")," - ", VLOOKUP(Table164[[#This Row],[Article]],'Data Validation'!$A$2:$B$16,2,FALSE)," - ",TEXT(Table164[[#This Row],[Series Number]],"0000")," - ",TEXT(VLOOKUP(Table164[[#This Row],[Location]],'Data Validation'!$A$20:$B$47,2,FALSE),"00")) -> #N/A | P37: =Table164[[#This Row],[Unit Value]]*Table164[[#This Row],[Qty | PCount]] -> 0 | Q37: =IF(Table164[[#This Row],[Unit Value]]<=4999,"Low-Value Asset","High-Value Asset") -> Low-Value Asset | AA37: =CONCATENATE(Table164[[#This Row],[Other Description]]," - ",IF(Table164[[#This Row],[Brand]]="n|a","",CONCATENATE("Brand: ",Table164[[#This Row],[Brand]]," - ")),IF(Table164[[#This Row],[Model]]="n|a","",CONCATENATE("Model: ",Table164[[#This Row],[Model]]," - ")),IF(Table164[[#This Row],[Serial Number]]="n|a","",CONCATENATE("SN: ",Table164[[#This Row],[Serial Number]]," - ")),IF(Table164[[#This Row],[Processor]]="n|a","",CONCATENATE("Processor: ",Table164[[#This Row],[Processor]]," - ")),IF(Table164[[#This Row],[RAM]]="n|a","",CONCATENATE("RAM: ",Table164[[#This Row],[RAM]]," - ")),IF(Table164[[#This Row],[Storage]]="n|a","",CONCATENATE("Storage: ",Table164[[#This Row],[Storage]]," - ")),IF(Table164[[#This Row],[Color]]="n|a","",CONCATENATE("Color: ",Table164[[#This Row],[Color]]))) -> - Brand: - Model: - SN: - Processor: - RAM: - Storage: - Color:
D38: =CONCATENATE(TEXT(Table164[[#This Row],[Date of Acquisition]],"yyyy")," - ", VLOOKUP(Table164[[#This Row],[Article]],'Data Validation'!$A$2:$B$16,2,FALSE)," - ",TEXT(Table164[[#This Row],[Series Number]],"0000")," - ",TEXT(VLOOKUP(Table164[[#This Row],[Location]],'Data Validation'!$A$20:$B$47,2,FALSE),"00")) -> #N/A | P38: =Table164[[#This Row],[Unit Value]]*Table164[[#This Row],[Qty | PCount]] -> 0 | Q38: =IF(Table164[[#This Row],[Unit Value]]<=4999,"Low-Value Asset","High-Value Asset") -> Low-Value Asset | AA38: =CONCATENATE(Table164[[#This Row],[Other Description]]," - ",IF(Table164[[#This Row],[Brand]]="n|a","",CONCATENATE("Brand: ",Table164[[#This Row],[Brand]]," - ")),IF(Table164[[#This Row],[Model]]="n|a","",CONCATENATE("Model: ",Table164[[#This Row],[Model]]," - ")),IF(Table164[[#This Row],[Serial Number]]="n|a","",CONCATENATE("SN: ",Table164[[#This Row],[Serial Number]]," - ")),IF(Table164[[#This Row],[Processor]]="n|a","",CONCATENATE("Processor: ",Table164[[#This Row],[Processor]]," - ")),IF(Table164[[#This Row],[RAM]]="n|a","",CONCATENATE("RAM: ",Table164[[#This Row],[RAM]]," - ")),IF(Table164[[#This Row],[Storage]]="n|a","",CONCATENATE("Storage: ",Table164[[#This Row],[Storage]]," - ")),IF(Table164[[#This Row],[Color]]="n|a","",CONCATENATE("Color: ",Table164[[#This Row],[Color]]))) -> - Brand: - Model: - SN: - Processor: - RAM: - Storage: - Color:
D39: =CONCATENATE(TEXT(Table164[[#This Row],[Date of Acquisition]],"yyyy")," - ", VLOOKUP(Table164[[#This Row],[Article]],'Data Validation'!$A$2:$B$16,2,FALSE)," - ",TEXT(Table164[[#This Row],[Series Number]],"0000")," - ",TEXT(VLOOKUP(Table164[[#This Row],[Location]],'Data Validation'!$A$20:$B$47,2,FALSE),"00")) -> #N/A | P39: =Table164[[#This Row],[Unit Value]]*Table164[[#This Row],[Qty | PCount]] -> 0 | Q39: =IF(Table164[[#This Row],[Unit Value]]<=4999,"Low-Value Asset","High-Value Asset") -> Low-Value Asset | AA39: =CONCATENATE(Table164[[#This Row],[Other Description]]," - ",IF(Table164[[#This Row],[Brand]]="n|a","",CONCATENATE("Brand: ",Table164[[#This Row],[Brand]]," - ")),IF(Table164[[#This Row],[Model]]="n|a","",CONCATENATE("Model: ",Table164[[#This Row],[Model]]," - ")),IF(Table164[[#This Row],[Serial Number]]="n|a","",CONCATENATE("SN: ",Table164[[#This Row],[Serial Number]]," - ")),IF(Table164[[#This Row],[Processor]]="n|a","",CONCATENATE("Processor: ",Table164[[#This Row],[Processor]]," - ")),IF(Table164[[#This Row],[RAM]]="n|a","",CONCATENATE("RAM: ",Table164[[#This Row],[RAM]]," - ")),IF(Table164[[#This Row],[Storage]]="n|a","",CONCATENATE("Storage: ",Table164[[#This Row],[Storage]]," - ")),IF(Table164[[#This Row],[Color]]="n|a","",CONCATENATE("Color: ",Table164[[#This Row],[Color]]))) -> - Brand: - Model: - SN: - Processor: - RAM: - Storage: - Color:
D40: =CONCATENATE(TEXT(Table164[[#This Row],[Date of Acquisition]],"yyyy")," - ", VLOOKUP(Table164[[#This Row],[Article]],'Data Validation'!$A$2:$B$16,2,FALSE)," - ",TEXT(Table164[[#This Row],[Series Number]],"0000")," - ",TEXT(VLOOKUP(Table164[[#This Row],[Location]],'Data Validation'!$A$20:$B$47,2,FALSE),"00")) -> #N/A | P40: =Table164[[#This Row],[Unit Value]]*Table164[[#This Row],[Qty | PCount]] -> 0 | Q40: =IF(Table164[[#This Row],[Unit Value]]<=4999,"Low-Value Asset","High-Value Asset") -> Low-Value Asset | AA40: =CONCATENATE(Table164[[#This Row],[Other Description]]," - ",IF(Table164[[#This Row],[Brand]]="n|a","",CONCATENATE("Brand: ",Table164[[#This Row],[Brand]]," - ")),IF(Table164[[#This Row],[Model]]="n|a","",CONCATENATE("Model: ",Table164[[#This Row],[Model]]," - ")),IF(Table164[[#This Row],[Serial Number]]="n|a","",CONCATENATE("SN: ",Table164[[#This Row],[Serial Number]]," - ")),IF(Table164[[#This Row],[Processor]]="n|a","",CONCATENATE("Processor: ",Table164[[#This Row],[Processor]]," - ")),IF(Table164[[#This Row],[RAM]]="n|a","",CONCATENATE("RAM: ",Table164[[#This Row],[RAM]]," - ")),IF(Table164[[#This Row],[Storage]]="n|a","",CONCATENATE("Storage: ",Table164[[#This Row],[Storage]]," - ")),IF(Table164[[#This Row],[Color]]="n|a","",CONCATENATE("Color: ",Table164[[#This Row],[Color]]))) -> - Brand: - Model: - SN: - Processor: - RAM: - Storage: - Color:
