Workbook

Sheet Sheet2
H1: {=_xlfn.XLOOKUP(D5,#REF!,CONCATENATE("Fund Source: ",#REF!))} -> #REF! | Q1: {=_xlfn.XLOOKUP(M5,#REF!,CONCATENATE("Fund Source: ",#REF!))} -> #REF!
B4: ICS NUMBER | C4: : | D4: =_xlfn.XLOOKUP(D5,#REF!,#REF!) -> #REF! | K4: ICS NUMBER | L4: : | M4: =_xlfn.XLOOKUP(M5,#REF!,#REF!) -> #REF!
B5: PROPERTY NUMBER | C5: : | D5: 2024 - 05 - 03 - 0004 - 01C | K5: PROPERTY NUMBER | L5: : | M5: 2024 - 05 - 03 - 0005 - 01C
B6: ASSET CLASSIFICATION | C6: : | D6: =_xlfn.XLOOKUP(D5,#REF!,#REF!) -> #REF! | K6: ASSET CLASSIFICATION | L6: : | M6: =_xlfn.XLOOKUP(M5,#REF!,#REF!) -> #REF!
B7: ITEM|BRAND|MODEL | C7: : | D7: {=_xlfn.XLOOKUP(D5,#REF!,CONCATENATE(IF(#REF!="n|a"," ",#REF!)," | ",IF(#REF!="n|a"," ",#REF!)))} -> #REF! | K7: ITEM|BRAND|MODEL | L7: : | M7: {=_xlfn.XLOOKUP(M5,#REF!,CONCATENATE(IF(#REF!="n|a"," ",#REF!)," | ",IF(#REF!="n|a"," ",#REF!)))} -> #REF!
B8: SERIAL NUMBER | C8: : | D8: =_xlfn.XLOOKUP(D5,#REF!,#REF!) -> #REF! | K8: SERIAL NUMBER | L8: : | M8: =_xlfn.XLOOKUP(M5,#REF!,#REF!) -> #REF!
B9: ACQUISITION COST | C9: : | D9: =_xlfn.XLOOKUP(D5,#REF!,#REF!) -> #REF! | E9: ACQUISITION DATE | F9: : | G9: =TEXT(_xlfn.XLOOKUP(D5,#REF!,#REF!),"mm.dd.yyyy") -> #REF! | K9: ACQUISITION COST | L9: : | M9: =_xlfn.XLOOKUP(M5,#REF!,#REF!) -> #REF! | N9: ACQUISITION DATE | O9: : | P9: =_xlfn.XLOOKUP(M5,#REF!,#REF!) -> #REF!
B10: PERSON ACCOUNTABLE | C10: : | D10: =_xlfn.XLOOKUP(D5,#REF!,#REF!) -> #REF! | K10: PERSON ACCOUNTABLE | L10: : | M10: =_xlfn.XLOOKUP(M5,#REF!,#REF!) -> #REF!
B11: VALIDATION | SIGNATURE | C11: : | K11: VALIDATION | SIGNATURE | L11: :
B12: "Removing or tampering of this sticker is punishable by law" | K12: "Removing or tampering of this sticker is punishable by law"
H16: {=_xlfn.XLOOKUP(D20,#REF!,CONCATENATE("Fund Source: ",#REF!))} -> #REF! | Q16: {=_xlfn.XLOOKUP(M20,#REF!,CONCATENATE("Fund Source: ",#REF!))} -> #REF!
B19: ICS NUMBER | C19: : | D19: =_xlfn.XLOOKUP(D20,#REF!,#REF!) -> #REF! | K19: ICS NUMBER | L19: : | M19: =_xlfn.XLOOKUP(M20,#REF!,#REF!) -> #REF!
B20: PROPERTY NUMBER | C20: : | D20: 2024 - 05 - 03 - 0006 - 01B | K20: PROPERTY NUMBER | L20: : | M20: 2024 - 05 - 03 - 0007 - 01A
B21: ASSET CLASSIFICATION | C21: : | D21: =_xlfn.XLOOKUP(D20,#REF!,#REF!) -> #REF! | K21: ASSET CLASSIFICATION | L21: : | M21: =_xlfn.XLOOKUP(M20,#REF!,#REF!) -> #REF!
B22: ITEM|BRAND|MODEL | C22: : | D22: {=_xlfn.XLOOKUP(D20,#REF!,CONCATENATE(IF(#REF!="n|a"," ",#REF!)," | ",IF(#REF!="n|a"," ",#REF!)))} -> #REF! | K22: ITEM|BRAND|MODEL | L22: : | M22: {=_xlfn.XLOOKUP(M20,#REF!,CONCATENATE(IF(#REF!="n|a"," ",#REF!)," | ",IF(#REF!="n|a"," ",#REF!)))} -> #REF!
B23: SERIAL NUMBER | C23: : | D23: =_xlfn.XLOOKUP(D20,#REF!,#REF!) -> #REF! | K23: SERIAL NUMBER | L23: : | M23: =_xlfn.XLOOKUP(M20,#REF!,#REF!) -> #REF!
B24: ACQUISITION COST | C24: : | D24: =_xlfn.XLOOKUP(D20,#REF!,#REF!) -> #REF! | E24: ACQUISITION DATE | F24: : | G24: =_xlfn.XLOOKUP(D20,#REF!,#REF!) -> #REF! | K24: ACQUISITION COST | L24: : | M24: =_xlfn.XLOOKUP(M20,#REF!,#REF!) -> #REF! | N24: ACQUISITION DATE | O24: : | P24: =_xlfn.XLOOKUP(M20,#REF!,#REF!) -> #REF!
B25: PERSON ACCOUNTABLE | C25: : | D25: =_xlfn.XLOOKUP(D20,#REF!,#REF!) -> #REF! | K25: PERSON ACCOUNTABLE | L25: : | M25: =_xlfn.XLOOKUP(M20,#REF!,#REF!) -> #REF!
B26: VALIDATION | SIGNATURE | C26: : | K26: VALIDATION | SIGNATURE | L26: :
B27: "Removing or tampering of this sticker is punishable by law" | K27: "Removing or tampering of this sticker is punishable by law"
H31: {=_xlfn.XLOOKUP(D35,#REF!,CONCATENATE("Fund Source: ",#REF!))} -> #REF! | Q31: {=_xlfn.XLOOKUP(M35,#REF!,CONCATENATE("Fund Source: ",#REF!))} -> #REF!
B34: ICS NUMBER | C34: : | D34: =_xlfn.XLOOKUP(D35,#REF!,#REF!) -> #REF! | K34: ICS NUMBER | L34: : | M34: =_xlfn.XLOOKUP(M35,#REF!,#REF!) -> #REF!
B35: PROPERTY NUMBER | C35: : | D35: 2024 - 05 - 03 - 0008 - 02B | K35: PROPERTY NUMBER | L35: : | M35: 2024 - 05 - 03 - 0009 - 01E
B36: ASSET CLASSIFICATION | C36: : | D36: =_xlfn.XLOOKUP(D35,#REF!,#REF!) -> #REF! | K36: ASSET CLASSIFICATION | L36: : | M36: =_xlfn.XLOOKUP(M35,#REF!,#REF!) -> #REF!
B37: ITEM|BRAND|MODEL | C37: : | D37: {=_xlfn.XLOOKUP(D35,#REF!,CONCATENATE(IF(#REF!="n|a"," ",#REF!)," | ",IF(#REF!="n|a"," ",#REF!)))} -> #REF! | K37: ITEM|BRAND|MODEL | L37: : | M37: {=_xlfn.XLOOKUP(M35,#REF!,CONCATENATE(IF(#REF!="n|a"," ",#REF!)," | ",IF(#REF!="n|a"," ",#REF!)))} -> #REF!
B38: SERIAL NUMBER | C38: : | D38: =_xlfn.XLOOKUP(D35,#REF!,#REF!) -> #REF! | K38: SERIAL NUMBER | L38: : | M38: =_xlfn.XLOOKUP(M35,#REF!,#REF!) -> #REF!
B39: ACQUISITION COST | C39: : | D39: =_xlfn.XLOOKUP(D35,#REF!,#REF!) -> #REF! | E39: ACQUISITION DATE | F39: : | G39: =_xlfn.XLOOKUP(D35,#REF!,#REF!) -> #REF! | K39: ACQUISITION COST | L39: : | M39: =_xlfn.XLOOKUP(M35,#REF!,#REF!) -> #REF! | N39: ACQUISITION DATE | O39: : | P39: =_xlfn.XLOOKUP(M35,#REF!,#REF!) -> #REF!
B40: PERSON ACCOUNTABLE | C40: : | D40: =_xlfn.XLOOKUP(D35,#REF!,#REF!) -> #REF! | K40: PERSON ACCOUNTABLE | L40: : | M40: =_xlfn.XLOOKUP(M35,#REF!,#REF!) -> #REF!
B41: VALIDATION | SIGNATURE | C41: : | K41: VALIDATION | SIGNATURE | L41: :
B42: "Removing or tampering of this sticker is punishable by law" | K42: "Removing or tampering of this sticker is punishable by law"
H46: {=_xlfn.XLOOKUP(D50,#REF!,CONCATENATE("Fund Source: ",#REF!))} -> #REF! | Q46: {=_xlfn.XLOOKUP(M50,#REF!,CONCATENATE("Fund Source: ",#REF!))} -> #REF!
B49: ICS NUMBER | C49: : | D49: =_xlfn.XLOOKUP(D50,#REF!,#REF!) -> #REF! | K49: ICS NUMBER | L49: : | M49: =_xlfn.XLOOKUP(M50,#REF!,#REF!) -> #REF!
B50: PROPERTY NUMBER | C50: : | D50: 2024 - 05 - 03 - 0010 - 01D | K50: PROPERTY NUMBER | L50: : | M50: 2024 - 05 - 03 - 0011 - 03A
B51: ASSET CLASSIFICATION | C51: : | D51: =_xlfn.XLOOKUP(D50,#REF!,#REF!) -> #REF! | K51: ASSET CLASSIFICATION | L51: : | M51: =_xlfn.XLOOKUP(M50,#REF!,#REF!) -> #REF!
B52: ITEM|BRAND|MODEL | C52: : | D52: {=_xlfn.XLOOKUP(D50,#REF!,CONCATENATE(IF(#REF!="n|a"," ",#REF!)," | ",IF(#REF!="n|a"," ",#REF!)))} -> #REF! | K52: ITEM|BRAND|MODEL | L52: : | M52: {=_xlfn.XLOOKUP(M50,#REF!,CONCATENATE(IF(#REF!="n|a"," ",#REF!)," | ",IF(#REF!="n|a"," ",#REF!)))} -> #REF!
B53: SERIAL NUMBER | C53: : | D53: =_xlfn.XLOOKUP(D50,#REF!,#REF!) -> #REF! | K53: SERIAL NUMBER | L53: : | M53: =_xlfn.XLOOKUP(M50,#REF!,#REF!) -> #REF!
B54: ACQUISITION COST | C54: : | D54: =_xlfn.XLOOKUP(D50,#REF!,#REF!) -> #REF! | E54: ACQUISITION DATE | F54: : | G54: =_xlfn.XLOOKUP(D50,#REF!,#REF!) -> #REF! | K54: ACQUISITION COST | L54: : | M54: =_xlfn.XLOOKUP(M50,#REF!,#REF!) -> #REF! | N54: ACQUISITION DATE | O54: : | P54: =_xlfn.XLOOKUP(M50,#REF!,#REF!) -> #REF!
B55: PERSON ACCOUNTABLE | C55: : | D55: =_xlfn.XLOOKUP(D50,#REF!,#REF!) -> #REF! | K55: PERSON ACCOUNTABLE | L55: : | M55: =_xlfn.XLOOKUP(M50,#REF!,#REF!) -> #REF!
B56: VALIDATION | SIGNATURE | C56: : | K56: VALIDATION | SIGNATURE | L56: :
B57: "Removing or tampering of this sticker is punishable by law" | K57: "Removing or tampering of this sticker is punishable by law"

Sheet List
A1: No. | B1: SN | C1: PAR No. | D1: Quantity | E1: Unit | F1: YEAR | G1: UACS | H1: SERIES | I1: LOCATION CODE | J1: Property Number | K1: Date Acquired | L1: Amount | M1: Received by | N1: Position | Designation | O1: Column1
A2: 17 | B2: 1PV6QG3 | C2: PAR 2022 - 01 - 0002 | D2: 1 | E2: unit | F2: 2022 | G2: 05 - 03 | H2: 60 | I2: 001G | J2: =_xlfn.CONCAT(Table1[[#This Row],[YEAR]]," - ",Table1[[#This Row],[UACS]]," - ",TEXT(Table1[[#This Row],[SERIES]],"0000")," - ",TEXT(Table1[[#This Row],[LOCATION CODE]],"00")) -> 2022 - 05 - 03 - 0060 - 001G | K2: 44581 | L2: 58270 | M2: CHARLIE P. CABATAN | N2: ADMINISTRATIVE OFFICER V
A3: 18 | B3: 6K9JPG3 | 7K9JPG3 | 7NV6QG3 | 5WW6QG3 | 6XW6QG3 | 9MV6QG3 | 2L9JPG3 | 7PV6QG3 | 9L9JPG3 | DK9JPG3 | 3N9JPG3 | 6M9JPG3 | 3NV6QG3 | HK9JPG3 | 4NV6QG3 | 8XW6QG3 | GNV6QG3 | C3: PAR 2022 - 01 - 0001 | D3: 17 | E3: unit | F3: 2022 | G3: 05 - 03 | H3: 76 | I3: 001C | J3: =_xlfn.CONCAT(Table1[[#This Row],[YEAR]]," - ",Table1[[#This Row],[UACS]]," - ",TEXT(Table1[[#This Row],[SERIES]],"0000")," - ",TEXT(Table1[[#This Row],[LOCATION CODE]],"00")) -> 2022 - 05 - 03 - 0076 - 001C | K3: 44600 | L3: 58270 | M3: JAYSON B. ANTIG | N3: INFORMATION TECHNOLOGY OFFICER I
A4: 19 | B4: 7VW6QG3 | 8WW6QG3 | 4VW6QG3 | 1WW6QG3 | FT26QG3 | JWW6QG3 | 5VW6QG3 | 6WW6QG3 | CTW6QG3 | BXW6QG3 | 9PV6QG3 | 4XW6QG3 | FM9JPG3 | 2N9JPG3 | 4N9JPG3 | 6N9JPG3 | CXW6QG3 | C4: PAR 2022 - 01 - 0019 | D4: 17 | E4: unit | F4: 2022 | G4: 05 - 03 | H4: 77 | I4: 4 | J4: =_xlfn.CONCAT(Table1[[#This Row],[YEAR]]," - ",Table1[[#This Row],[UACS]]," - ",TEXT(Table1[[#This Row],[SERIES]],"0000")," - ",TEXT(Table1[[#This Row],[LOCATION CODE]],"00")) -> 2022 - 05 - 03 - 0077 - 04 | K4: 44600 | L4: 58270 | M4: DANAH LEI A. PUGAY | N4: ADMINISTRATIVE OFFICER II
A5: 20 | B5: BMV6QG3 | 2PV6QG3 | JLV6QG3 | 5NV6QG3 | GM9JPG3 | HVW6QG3 | HLV6QG3 | 7MV6QG3 | 1MV6QG3 | 8NV6QG3 | DXW6QG3 | 1L9JPG3 | C5: PAR 2022 - 01 - 0020 | D5: 12 | E5: unit | F5: 2022 | G5: 05 - 03 | H5: 78 | I5: 5 | J5: =_xlfn.CONCAT(Table1[[#This Row],[YEAR]]," - ",Table1[[#This Row],[UACS]]," - ",TEXT(Table1[[#This Row],[SERIES]],"0000")," - ",TEXT(Table1[[#This Row],[LOCATION CODE]],"00")) -> 2022 - 05 - 03 - 0078 - 05 | K5: 44600 | L5: 58270 | M5: ABIGAIL B. ZAPANTA | N5: ADMINISTRATIVE OFFICER II
A6: 21 | B6: 2NV6QG3 | DMV6QG3 | JNV6QG3 | CLV6QG3 | 6NV6QG3 | 5N9JPG3 | HL9JPG3 | 6PV6QG3 | FK9JPG3 | C6: PAR 2022 - 01 - 0021 | D6: 9 | E6: unit | F6: 2022 | G6: 05 - 03 | H6: 79 | I6: 6 | J6: =_xlfn.CONCAT(Table1[[#This Row],[YEAR]]," - ",Table1[[#This Row],[UACS]]," - ",TEXT(Table1[[#This Row],[SERIES]],"0000")," - ",TEXT(Table1[[#This Row],[LOCATION CODE]],"00")) -> 2022 - 05 - 03 - 0079 - 06 | K6: 44600 | L6: 58270 | M6: CAREN JOY BARRERA | N6: ADMINISTRATIVE OFFICER II
A7: 22 | B7: 1NV6QG3 | 9LV6QG3 | CMV6QG3 | JL9JPG3 | 2M9JPG3 | C7: PAR 2022 - 01 - 0022 | D7: 5 | E7: unit | F7: 2022 | G7: 05 - 03 | H7: 80 | I7: 7 | J7: =_xlfn.CONCAT(Table1[[#This Row],[YEAR]]," - ",Table1[[#This Row],[UACS]]," - ",TEXT(Table1[[#This Row],[SERIES]],"0000")," - ",TEXT(Table1[[#This Row],[LOCATION CODE]],"00")) -> 2022 - 05 - 03 - 0080 - 07 | K7: 44600 | L7: 58270 | M7: J-ANN G. BENTIR | N7: ADMINISTRATIVE OFFICER II
A8: 23 | B8: FNV6QG3 | DL9JPG3 | CK9JPG3 | 5M9JPG3 | FL9JPG3 | C8: PAR 2022 - 01 - 0023 | D8: 5 | E8: unit | F8: 2022 | G8: 05 - 03 | H8: 81 | I8: 8 | J8: =_xlfn.CONCAT(Table1[[#This Row],[YEAR]]," - ",Table1[[#This Row],[UACS]]," - ",TEXT(Table1[[#This Row],[SERIES]],"0000")," - ",TEXT(Table1[[#This Row],[LOCATION CODE]],"00")) -> 2022 - 05 - 03 - 0081 - 08 | K8: 44600 | L8: 58270 | M8: PAULO A. REYES | N8: ADMINISTRATIVE OFFICER II
A9: 24 | B9: 3M9JPG3 | 8L9JPG3 | GL9JPG3 | 5L9JPG3 | 7M9JPG3 | C9: PAR 2022 - 01 - 0024 | D9: 5 | E9: unit | F9: 2022 | G9: 05 - 03 | H9: 82 | I9: 9 | J9: =_xlfn.CONCAT(Table1[[#This Row],[YEAR]]," - ",Table1[[#This Row],[UACS]]," - ",TEXT(Table1[[#This Row],[SERIES]],"0000")," - ",TEXT(Table1[[#This Row],[LOCATION CODE]],"00")) -> 2022 - 05 - 03 - 0082 - 09 | K9: 44600 | L9: 58270 | M9: ANNE ROYAL D. SUMA-OY | N9: ADMINISTRATIVE OFFICER II
A10: 25 | B10: BPV6QG3 |8K9JPG3 | CWW6QG3 | 7XW6QG3 | C10: PAR 2022 - 01 - 0025 | D10: 4 | E10: unit | F10: 2022 | G10: 05 - 03 | H10: 83 | I10: 10 | J10: =_xlfn.CONCAT(Table1[[#This Row],[YEAR]]," - ",Table1[[#This Row],[UACS]]," - ",TEXT(Table1[[#This Row],[SERIES]],"0000")," - ",TEXT(Table1[[#This Row],[LOCATION CODE]],"00")) -> 2022 - 05 - 03 - 0083 - 10 | K10: 44600 | L10: 58270 | M10: MARIJOY N. BUMANGLAG | N10: ADMINISTRATIVE OFFICER II
A11: 26 | B11: 5PV6QG3 | BL9JPG3 | 2MV6QG3 | C11: PAR 2022 - 01 - 0026 | D11: 3 | E11: unit | F11: 2022 | G11: 05 - 03 | H11: 84 | I11: 11 | J11: =_xlfn.CONCAT(Table1[[#This Row],[YEAR]]," - ",Table1[[#This Row],[UACS]]," - ",TEXT(Table1[[#This Row],[SERIES]],"0000")," - ",TEXT(Table1[[#This Row],[LOCATION CODE]],"00")) -> 2022 - 05 - 03 - 0084 - 11 | K11: 44600 | L11: 58270 | M11: CATHERINE C. MELO | N11: ADMINISTRATIVE OFFICER II
A12: 27 | B12: 6MV6QG3 | FLV6QG3 | C12: PAR 2022 - 01 - 0027 | D12: 2 | E12: unit | F12: 2022 | G12: 05 - 03 | H12: 85 | I12: 12 | J12: =_xlfn.CONCAT(Table1[[#This Row],[YEAR]]," - ",Table1[[#This Row],[UACS]]," - ",TEXT(Table1[[#This Row],[SERIES]],"0000")," - ",TEXT(Table1[[#This Row],[LOCATION CODE]],"00")) -> 2022 - 05 - 03 - 0085 - 12 | K12: 44600 | L12: 58270 | M12: CATHERINE C. MELO | N12: ADMINISTRATIVE OFFICER II
A13: 28 | B13: 8M9JPG3 | 7N9JPG3 | C13: PAR 2022 - 01 - 0028 | D13: 2 | E13: unit | F13: 2022 | G13: 05 - 03 | H13: 86 | I13: 13 | J13: =_xlfn.CONCAT(Table1[[#This Row],[YEAR]]," - ",Table1[[#This Row],[UACS]]," - ",TEXT(Table1[[#This Row],[SERIES]],"0000")," - ",TEXT(Table1[[#This Row],[LOCATION CODE]],"00")) -> 2022 - 05 - 03 - 0086 - 13 | K13: 44600 | L13: 58270 | M13: JELLENE M. VILLAFLOR | N13: PROJECT DEVELOPMENT OFFICER I
A14: 29 | B14: BM9JPG3 | C14: PAR 2022 - 01 - 0029 | D14: 1 | E14: unit | F14: 2022 | G14: 05 - 03 | H14: 87 | I14: 14 | J14: =_xlfn.CONCAT(Table1[[#This Row],[YEAR]]," - ",Table1[[#This Row],[UACS]]," - ",TEXT(Table1[[#This Row],[SERIES]],"0000")," - ",TEXT(Table1[[#This Row],[LOCATION CODE]],"00")) -> 2022 - 05 - 03 - 0087 - 14 | K14: 44600 | L14: 58270 | M14: JELLENE M. VILLAFLOR | N14: PROJECT DEVELOPMENT OFFICER I
A15: 30 | B15: 4M9JPG3 | C15: PAR 2022 - 01 - 0030 | D15: 1 | E15: unit | F15: 2022 | G15: 05 - 03 | H15: 88 | I15: 15 | J15: =_xlfn.CONCAT(Table1[[#This Row],[YEAR]]," - ",Table1[[#This Row],[UACS]]," - ",TEXT(Table1[[#This Row],[SERIES]],"0000")," - ",TEXT(Table1[[#This Row],[LOCATION CODE]],"00")) -> 2022 - 05 - 03 - 0088 - 15 | K15: 44600 | L15: 58270 | M15: PAULO A. REYES | N15: ADMINISTRATIVE OFFICER II
... A19: 34 | B19: DWW6QG3 | 5XW6QG3 | JTW6QG3 | C19: PAR 2022 - 01 - 0034 | D19: 3 | E19: unit | F19: 2022 | G19: 05 - 03 | H19: 92 | I19: 19 | J19: =_xlfn.CONCAT(Table1[[#This Row],[YEAR]]," - ",Table1[[#This Row],[UACS]]," - ",TEXT(Table1[[#This Row],[SERIES]],"0000")," - ",TEXT(Table1[[#This Row],[LOCATION CODE]],"00")) -> 2022 - 05 - 03 - 0092 - 19 | K19: 44600 | L19: 58270 | M19: ANNALYN S. SALANGSANG | N19: ADMINISTRATIVE ASSISTANT II

Sheet Sheet1
A1: {=_xlfn.UNIQUE(Table1[PAR No.])} -> PAR 2022 - 01 - 0002 | D1: {=_xlfn.UNIQUE(#REF!)} -> #REF!
A2: PAR 2022 - 01 - 0001
A3: PAR 2022 - 01 - 0019
A4: PAR 2022 - 01 - 0020
A5: PAR 2022 - 01 - 0021
A6: PAR 2022 - 01 - 0022
A7: PAR 2022 - 01 - 0023
A8: PAR 2022 - 01 - 0024
A9: PAR 2022 - 01 - 0025
A10: PAR 2022 - 01 - 0026
A11: PAR 2022 - 01 - 0027
A12: PAR 2022 - 01 - 0028
A13: PAR 2022 - 01 - 0029
... A18: PAR 2022 - 01 - 0034

Sheet PAR
B1: Appendix 71
B3: PROPERTY ACKNOWLEDGEMENT RECEIPT
B5: Entity Name: | C5: Department of Education
B6: Fund Cluster: | C6: 1101101 | H6: PAR NO: | I6: PAR 2022 - 01 - 0001
A8: QTY | C8: UNIT | D8: DESCRIPTION | H8: PROPERTY NO. | I8: DATE ACQUIRED | J8: AMOUNT
A9: =_xlfn.XLOOKUP($I$6,Table1[PAR No.],Table1[Quantity]) -> 17 | C9: =_xlfn.XLOOKUP($I$6,Table1[PAR No.],Table1[Unit]) -> unit | D9: Laptop (Bayanihan II Funds) | I9: =_xlfn.XLOOKUP($I$6,Table1[PAR No.],Table1[[Date Acquired ]]) -> 44600 | J9: =_xlfn.XLOOKUP($I$6,Table1[PAR No.],Table1[Amount])*A9 -> 990590
D10: DELL Latitude 324 Laptop
D11: Processor: Intel Celeron 6305 1.8 GHz, 2C
D12: Memory: 8GB DDR4, 3200 MHz, SODIMM
D13: Screen Size: 14" FHD, 1920 x 1080, 60GHz
D14: non-touch
D15: Storage: 1TB, 5400 RPM, SATA, HDD
D16: Camera: Built - In
D17: Connectivity: Intel Wifi 6 AX 201
D18: Bluetooth: 5.1
D19: Ports:
D20: 1 x USB 3.2, 2 x 2 type C port with display
D21: port alt mode power delivery
... D45: Serial Numbers:
D46: =M46 -> 6K9JPG3 | H46: 2022 - 05 - 03 - 0059 - 001C | M46: 6K9JPG3
D47: 7K9JPG3 | H47: 2022 - 05 - 03 - 0061 - 001C | M47: DLV6QG3
D48: =M48 -> 7NV6QG3 | H48: 2022 - 05 - 03 - 0062 - 001C | M48: 7NV6QG3
D49: =M49 -> 5WW6QG3 | H49: 2022 - 05 - 03 - 0063 - 001C | M49: 5WW6QG3
D50: =M50 -> 6XW6QG3 | H50: 2022 - 05 - 03 - 0064 - 001C | M50: 6XW6QG3
D51: =M51 -> 9MV6QG3 | H51: 2022 - 05 - 03 - 0065 - 001C | M51: 9MV6QG3
D52: =M52 -> 2L9JPG3 | H52: 2022 - 05 - 03 - 0066 - 001C | M52: 2L9JPG3
D53: =M53 -> 7PV6QG3 | H53: 2022 - 05 - 03 - 0067 - 001C | M53: 7PV6QG3
D54: =M54 -> 9L9JPG3 | H54: 2022 - 05 - 03 - 0068 - 001C | M54: 9L9JPG3
D55: =M55 -> DK9JPG3 | H55: 2022 - 05 - 03 - 0069 - 001C | M55: DK9JPG3
D56: =M56 -> 3N9JPG3 | H56: 2022 - 05 - 03 - 0070 - 001C | M56: 3N9JPG3
D57: =M57 -> 6M9JPG3 | H57: 2022 - 05 - 03 - 0071 - 001C | M57: 6M9JPG3
D58: =M58 -> 3NV6QG3 | H58: 2022 - 05 - 03 - 0072 - 001C | M58: 3NV6QG3
D59: HK9JPG3 | H59: 2022 - 05 - 03 - 0073 - 001C | M59: 9M9JPG3
D60: =M60 -> 4NV6QG3 | H60: 2022 - 05 - 03 - 0074 - 001C | M60: 4NV6QG3
D61: =M61 -> 8XW6QG3 | H61: 2022 - 05 - 03 - 0075 - 001C | M61: 8XW6QG3
D62: =M62 -> GNV6QG3 | H62: 2022 - 05 - 03 - 0076 - 001C | M62: GNV6QG3
A63: x ---------- Nothing Follows ---------- x
I65: Total | J65: =SUM(J9:K50) -> 990590
B94: Received by: | H94: Issued by:
B96: =_xlfn.XLOOKUP($I$6,Table1[PAR No.],Table1[Received by]) -> JAYSON B. ANTIG | H96: KARL MANUEL O. CORDORA
...

Sheet Sticker
B3: ICS No. | C3: Property No. | D3: Asset Classification | E3: Item | Brand | Model | F3: Serial No. | G3: Acquisition Cost | H3: Acquisition Date | I3: Issuance Date | J3: Location | K3: Accountable Person | L3: Fund Source
B4: PAR2022 - 01 - 0001 | C4: 2022 - 05 - 03 - 0059 - 001C | D4: ICT Equipment | E4: DELL Latitude 324 Laptop | F4: 6K9JPG3 | G4: 58270 | H4: 44567 | I4: 44779 | J4: 001C - Information and Communication Technology Unit | K4: Jayson B. Antig | L4: Central Office
B5: PAR2022 - 01 - 0002 | C5: 2022 - 05 - 03 - 0060 - 001G | D5: ICT Equipment | E5: DELL Latitude 324 Laptop | F5: 1PV6QG3 | G5: 58270 | H5: 44567 | I5: 44581 | J5: 001G - General Services | K5: Charlie P. Cabatan | L5: Central Office
B6: PAR2022 - 01 - 0001 | C6: 2022 - 05 - 03 - 0061 - 001C | D6: ICT Equipment | E6: DELL Latitude 324 Laptop | F6: 7K9JPG3 | G6: 58270 | H6: 44567 | I6: 44779 | J6: 001C - Information and Communication Technology Unit | K6: Jayson B. Antig | L6: Central Office
B7: PAR2022 - 01 - 0001 | C7: 2022 - 05 - 03 - 0062 - 001C | D7: ICT Equipment | E7: DELL Latitude 324 Laptop | F7: 7NV6QG3 | G7: 58270 | H7: 44567 | I7: 44779 | J7: 001C - Information and Communication Technology Unit | K7: Jayson B. Antig | L7: Central Office
B8: PAR2022 - 01 - 0001 | C8: 2022 - 05 - 03 - 0063 - 001C | D8: ICT Equipment | E8: DELL Latitude 324 Laptop | F8: 5WW6QG3 | G8: 58270 | H8: 44567 | I8: 44779 | J8: 001C - Information and Communication Technology Unit | K8: Jayson B. Antig | L8: Central Office
B9: PAR2022 - 01 - 0001 | C9: 2022 - 05 - 03 - 0064 - 001C | D9: ICT Equipment | E9: DELL Latitude 324 Laptop | F9: 6XW6QG3 | G9: 58270 | H9: 44567 | I9: 44779 | J9: 001C - Information and Communication Technology Unit | K9: Jayson B. Antig | L9: Central Office
B10: PAR2022 - 01 - 0001 | C10: 2022 - 05 - 03 - 0065 - 001C | D10: ICT Equipment | E10: DELL Latitude 324 Laptop | F10: 9MV6QG3 | G10: 58270 | H10: 44567 | I10: 44779 | J10: 001C - Information and Communication Technology Unit | K10: Jayson B. Antig | L10: Central Office
B11: PAR2022 - 01 - 0001 | C11: 2022 - 05 - 03 - 0066 - 001C | D11: ICT Equipment | E11: DELL Latitude 324 Laptop | F11: 2L9JPG3 | G11: 58270 | H11: 44567 | I11: 44779 | J11: 001C - Information and Communication Technology Unit | K11: Jayson B. Antig | L11: Central Office
B12: PAR2022 - 01 - 0001 | C12: 2022 - 05 - 03 - 0067 - 001C | D12: ICT Equipment | E12: DELL Latitude 324 Laptop | F12: 7PV6QG3 | G12: 58270 | H12: 44567 | I12: 44779 | J12: 001C - Information and Communication Technology Unit | K12: Jayson B. Antig | L12: Central Office
B13: PAR2022 - 01 - 0001 | C13: 2022 - 05 - 03 - 0068 - 001C | D13: ICT Equipment | E13: DELL Latitude 324 Laptop | F13: 9L9JPG3 | G13: 58270 | H13: 44567 | I13: 44779 | J13: 001C - Information and Communication Technology Unit | K13: Jayson B. Antig | L13: Central Office
B14: PAR2022 - 01 - 0001 | C14: 2022 - 05 - 03 - 0069 - 001C | D14: ICT Equipment | E14: DELL Latitude 324 Laptop | F14: DK9JPG3 | G14: 58270 | H14: 44567 | I14: 44779 | J14: 001C - Information and Communication Technology Unit | K14: Jayson B. Antig | L14: Central Office
B15: PAR2022 - 01 - 0001 | C15: 2022 - 05 - 03 - 0070 - 001C | D15: ICT Equipment | E15: DELL Latitude 324 Laptop | F15: 3N9JPG3 | G15: 58270 | H15: 44567 | I15: 44779 | J15: 001C - Information and Communication Technology Unit | K15: Jayson B. Antig | L15: Central Office
... B21: PAR2022 - 01 - 0001 | C21: 2022 - 05 - 03 - 0076 - 001C | D21: ICT Equipment | E21: DELL Latitude 324 Laptop | F21: GNV6QG3 | G21: 58270 | H21: 44567 | I21: 44779 | J21: 001C - Information and Communication Technology Unit | K21: Jayson B. Antig | L21: Central Office

Sheet Q1
B2: Republic of the Philippines
B3: Department of Education
B4: Region IV - A CALABARZON
B5: SCHOOLS DIVISION OFFICE OF CAVITE CITY
B6: City of Cavite
I7: 44648
I8: Date
B9: Business Name: | C9: PANDAYAN BOOKSHOP, INC.
B11: Dear Sir/Madam:
C13: Please quote your price for the purchase of
B14: listed hereunder to be used
B15: The supplies/materials will be delivered at the
B16: in accordance with the Advice of
A18: QUANTITY | C18: UNIT | E18: MATERIALS | PARTICULARS | I18: UNIT PRICE | J18: TOTAL
A19: =#REF! -> #REF! | C19: =#REF! -> #REF! | E19: =#REF! -> #REF! | I19: =#REF! -> #REF! | J19: =I19*A19 -> #REF!
A20: =#REF! -> #REF! | C20: =#REF! -> #REF! | E20: =#REF! -> #REF! | I20: =#REF! -> #REF! | J20: =I20*A20 -> #REF!
J21: =I21*A21 -> 0
J22: =I22*A22 -> 0
J23: =I23*A23 -> 0
J24: =I24*A24 -> 0
J25: =I25*A25 -> 0
J26: =I26*A26 -> 0
J27: =I27*A27 -> 0
J28: =I28*A28 -> 0
J29: =I29*A29 -> 0
J30: =I30*A30 -> 0
J31: =I31*A31 -> 0
J32: =I32*A32 -> 0
... J34: =I34*A34 -> 0
A57: Total: | J57: =SUM(J19:K56) -> #REF!
B60: JOSHUA AIRIS DE LEON | H60: KARL MANUEL O. CORDORA
B61: Signature over Printed Name | H61: Administrative Assistant III
H62: Designated Supply Officer

Sheet Q2
B2: Republic of the Philippines
B3: Department of Education
B4: Region IV - A CALABARZON
B5: SCHOOLS DIVISION OFFICE OF CAVITE CITY
B6: City of Cavite
I7: ='Q1'!I7 -> 44648
I8: Date
B9: Business Name: | C9: NETH'S EAT
B11: Dear Sir/Madam:
C13: Please quote your price for the purchase of | G13: ='Q1'!G13 -> 0
B14: listed hereunder to be used | D14: ='Q1'!D14 -> 0
B15: The supplies/materials will be delivered at the | F15: Schools Division Office of Cavite City
B16: in accordance with the Advice of
A18: QUANTITY | C18: UNIT | E18: MATERIALS | PARTICULARS | I18: UNIT PRICE | J18: TOTAL
A19: =#REF! -> #REF! | J19: =I19*A19 -> #REF!
J20: =I20*A20 -> 0
J21: =I21*A21 -> 0
J22: =I22*A22 -> 0
J23: =I23*A23 -> 0
J24: =I24*A24 -> 0
J25: =I25*A25 -> 0
J26: =I26*A26 -> 0
J27: =I27*A27 -> 0
J31: =I31*A31 -> 0
J32: =I32*A32 -> 0
J33: =I33*A33 -> 0
J34: =I34*A34 -> 0
A57: Total: | J57: =SUM(J19:K55) -> #REF!
B60: MARINEL S. DOMINGO | H60: KARL MANUEL O. CORDORA
B61: Signature over Printed Name | H61: Administrative Assistant III
H62: Designated Supply Officer

Sheet Q3
B2: Republic of the Philippines
B3: Department of Education
B4: Region IV - A CALABARZON
B5: SCHOOLS DIVISION OFFICE OF CAVITE CITY
B6: City of Cavite
I7: ='Q1'!I7 -> 44648
I8: Date
B9: Business Name: | C9: MACKY'S CATERING SERVICES
B11: Dear Sir/Madam:
C13: Please quote your price for the purchase of | G13: ='Q1'!G13 -> 0
B14: listed hereunder to be used | D14: ='Q1'!D14 -> 0
B15: The supplies/materials will be delivered at the | F15: Schools Division Office of Cavite City
B16: in accordance with the Advice of
A18: QUANTITY | C18: UNIT | E18: MATERIALS | PARTICULARS | I18: UNIT PRICE | J18: TOTAL
A19: =#REF! -> #REF! | J19: =I19*A19 -> #REF!
J20: =I20*A20 -> 0
J21: =I21*A21 -> 0
J22: =I22*A22 -> 0
J23: =I23*A23 -> 0
J24: =I24*A24 -> 0
J25: =I25*A25 -> 0
J26: =I26*A26 -> 0
J27: =I27*A27 -> 0
J28: =I28*A28 -> 0
J29: =I29*A29 -> 0
J30: =I30*A30 -> 0
J31: =I31*A31 -> 0
... J34: =I34*A34 -> 0
A57: Total: | J57: =SUM(J19:K55) -> #REF!
B60: MACKY SALIENDRA | H60: KARL MANUEL O. CORDORA
B61: Signature over Printed Name | H61: Administrative Assistant III
H62: Designated Supply Officer

Sheet PO
B2: PURCHASE ORDER
B3: DEPED CAVITE CITY
B4: Entity Name
B6: Supplier: | D6: COPYLANDIA OFFICE SYSTEMS CORPORATION | I6: PO No.: | J6: =#REF! -> #REF!
B7: Address: | D7: G/F SQH 1 Bldg., E. Aguinaldo Highway, Anabu 2F, Imus City | I7: Date: | J7: ='Q1'!I7 -> 44648
B8: TIN: | C8: 008-387-425-000 | I8: Mode of Procurement:
B10: Gentlemen: | F10: Please furnish this Office the following articles subject to the terms and conditions contained herein:
B14: Place of Delivery: | F14: Schools Division Office of Cavite City | I14: Delivery Term:
B15: Date of Delivery: | I15: Payment Term:
A17: Stock | Property No. | E17: Unit | G17: Description | I17: Qty | K17: Unit Cost | M17: Amount
E18: ='Q1'!C19 -> #REF! | G18: ='Q1'!E19 -> #REF! | I18: ='Q1'!A19 -> #REF! | K18: ='Q1'!I19 -> #REF! | M18: =I18*K18 -> #REF!
E19: ='Q1'!C20 -> #REF! | G19: ='Q1'!E20 -> #REF! | I19: ='Q1'!A20 -> #REF! | K19: ='Q1'!I20 -> #REF! | M19: =I19*K19 -> #REF!
K20: ='Q1'!I21 -> 0 | M20: =I20*K20 -> 0
K21: ='Q1'!I22 -> 0 | M21: =I21*K21 -> 0
K22: ='Q1'!I23 -> 0 | M22: =I22*K22 -> 0
K23: ='Q1'!I24 -> 0 | M23: =I23*K23 -> 0
K24: ='Q1'!I25 -> 0 | M24: =I24*K24 -> 0
K25: ='Q1'!I26 -> 0 | M25: =I25*K25 -> 0
K26: ='Q1'!I27 -> 0 | M26: =I26*K26 -> 0
K27: ='Q1'!I28 -> 0 | M27: =I27*K27 -> 0
K28: ='Q1'!I29 -> 0 | M28: =I28*K28 -> 0
K29: ='Q1'!I30 -> 0 | M29: =I29*K29 -> 0
K30: ='Q1'!I31 -> 0 | M30: =I30*K30 -> 0
K31: ='Q1'!I32 -> 0 | M31: =I31*K31 -> 0
... K33: ='Q1'!I34 -> 0 | M33: =I33*K33 -> 0
A44: Total: | M44: =SUM(M18:N43) -> #REF!
B45: (Total Amount in Words) | H45: Six Thousand Pesos
B47: In case of failure to make the full delivery within the time specified above, a penalty of one-tenth (1/10) of one percent for every day of delay shall be imposed on the undelivered item/s.
B50: Conforme: | I50: Very truly yours,
B52: JOSHUA AIRIS DE LEON | I52: EDGARDO B. MILITANTE
B53: Signature over Printed Name of Supplier | Representative | I53: Signature over Printed Name of Authorized Official
B54: ________________________________________ | I54: OIC, Schools Division Superintendent
B55: Date | I55: Designation
B57: Fund Cluster: | I57: ORS | BURS No.:
B58: Funds Available: | I58: Date of ORS | BURS:
I60: Amount: | K60: =M44 -> #REF!
A61: MICHELLE L. MATA
A62: Signature over Printed Name of Chief
A63: Accountant/Head of Accounting Division/Unit
